Workbook

Sheet README
A1: 填表须知
A2: 1. 不随车型变换的平台化接口和数据类型，填写到Interface_Platform和DataType_Platform中；和车型相关的接口和数据类型填写到Interface_T1GC和DataType_T1GC中 2. 输入Port和对应的输出Port要求同名（Interface-C列） 3. Port上的成员真正的数据类型是其对应的Rte_Type（Interface-D列） 4. 若接口需要缓存队列，对应的IsQueued（Interface-H列）置为Y，并且填写QueueLength（Interface-I列）,PR Port需保持一致 5. 如果需要获取接口在上次读取后是否被更新，可以将对应的IsUpdated(Interface-L列)置为Y 6. 数组类型的成员，需要在Interface表格中将F列填写为rt_Array_XXX_YYY,XXX为对应每个成员的数据类型,YYY为数组长度； 同时在DataType表格中对数组类型进行定义，填写结构体名称（A列），DataType(D列)和Dimensions（E列），名称为rt_Array_XXX_YYY，DataType为XXX，Dimensions为YYY 7. 结构体类型的成员，在DataType表格中起始列填写结构体名称（A列）和DataType(D列)，DataType写为Struct 接下来的几行填写Member成员信息(C列)及其成员类型（D列）。 8. 枚举类型的成员，在DataType表格中起始列填写结构体名称（A列）和DataType(D列)，DataType写为Enum 接下来的几行填写枚举的定义(C列)和对应值（D列） 9. 修改表格后请同步修改ChangeHistory，会同步到arxml的log中 10.建议swc名称遵循autosar_swc_xxx格式，周期runnable名称遵循autosar_swc_xxx_Step格式

Sheet ChangeHistory
A1: 每月22号锁定！
A2: 版本 Version | B2: 状态 Status | C2: 编制人 Author | D2: 编制日期 Modify Data | E2: 批准人 Approval | F2: 批准日期 Approval Data | G2: 内容描述 Details Description | H2: T1GC | I2: E01
A3: 0.0 | B3: Draft | C3: 程振宁 | D3: 20240522 | G3: 初版，删除部分无用接口 | H3: merged | I3: merged
C4: 姜宝祥 | D4: 20240522 | G4: 补充新版融合接口，仅包含输出接口 | H4: merged | I4: merged
C5: 李一凡 | D5: 20240522 | G5: 修复新版融合接口错误，增加enum定义。 | H5: merged | I5: merged
C6: 程振宁 | D6: 20240523 | G6: 调整融合输出结构体为header+elem | H6: merged | I6: merged
C7: 杨克强 | D7: 20240523 | G7: 1.信号虚拟模块的signal_adapt名字更新回val 2.hmi_adapter模块更名回HMI 3.删除部分无用的“Data Type Name”，如[VCAN_AcmBody_MSG_BUS/VCAN_Bodystatus_MSG_BUS/VCAN_BCUsts_MSG_BUS/VCAN_Motorsts_02_MSG_BUS/VCAN_Motorsts_01_MSG_BUS/VCAN_ABS_ESP_1_MSG_BUS/VCAN_ABS_ESP_3_MSG_BUS/VCAN_ABS_ESP_4_MSG_BUS/VCAN_ABS_ESP_7_MSG_BUS/VCAN_ABS_ESP_8_MSG_BUS/VCAN_BCM_1_MSG_BUS/VCAN_DMS_1_MSG_BUS/ 4.autosar_swc_nvmadapter融入val模块，即nvme模块的输入输出增加至val模块 5.新增VAL模块输出接口（someIP相关内容） 6.新增VAL模块输入接口（someIP相关内容） 7.新增VAL模块输入接口（控制相关信号） 8.新增VAL模块输出接口（控制相关信号） 9.删除VAL的原chery相关HMI接口 10.删除J3-swc相关内容，后续增加在VAL 11.新增DAI功能开关，更新VAL_Chery_SWITCH_RESP_BUS为VAL_SWITCH_RESP_BUS | H7: merged | I7: merged
C8: 王亚伟 | D8: 20240523 | G8: 1、修改rlgs输入输出端口名； 2、删除RFM的输入接口 | H8: merged | I8: merged
C9: 王程 | D9: 20240523 | G9: 1 增加 LONP_TrajPolyPara输出 datatype为 LONP_TrajPolyPara_BUS 2 增加 LONC_ACCReq输出 datatype为 LONC_ACCReq_BUS ,输入增加LONP_TrajPolyPara | H9: merged | I9: merged
C10: 姜宝祥 | D10: 20240524 | G10: swc_tos 接口变更 1 删除接口；(RFM_LINE_L1,RFM_LINE_L2,RFM_LINE_L3,RFM_LINE_R1,RFM_LINE_R2,RFM_LINE_R3,RFM_LINE_CL,RFM_LINE_LB,RFM_LINE_RB、EMA_JunctionExist); 2 新增接口； LATP_TARLINE；LATP_TARPATH； | H10: merged | I10: merged
C11: 李杭 | D11: 20240524 | G11: LATC输出接口变更 接口LATC_CTRL_OUT_BUS中增加成员LATC_IFCSteerMaxTqReq，LATC_IFCSteerMinTqReq | H11: merged | I11: merged
C12: 杨克强 | D12: 20240527 | G12: VAL模块输出的J3信号接口更新，将其他模块的查找替换 | H12: merged | I12: merged
C13: 王亚伟 | D13: 20240527 | G13: 在EHRV2_SEGMENT_INFO_BUS增加road_type信号 | H13: merged | I13: merged
C14: 李杭 | D14: 20240527 | G14: LATP添加接口VAL_J3_TFL，VAL_J3_RM 删除接口EMA_JunctionExist | H14: merged | I14: merged
C15: 杨克强 | D15: 20240529 | G15: 更新【SysOut_SWITCH_RESP_BUS】和【SysOut_SWITCH_RESP_BUS】中的DAIOnOff数据类型为uint8 | H15: merged | I15: merged
... C20: 姜宝祥 | D20: 20240626 | G20: 1 将TOS输出接口中，objec_ID(所有接口)数据类型变更为uint32,objec_age变更为uint64（hwa接口） 2 增加目标绝对纵向加速度属性； | H20: merged | I20: merged
D21: 20240629 | G21: 1 增加AEB模块的AEB的输入输出 | H21: merged | I21: merged
C22: 王亚伟 | D22: 20240701 | G22: 1、在EHRV2_NAV_STUB_BUS增加is_on_rout信号 | H22: merged | I22: merged
C23: 王亚伟 | D23: 20240703 | G23: 1、删除EHRV2_EGO_POSE_BUS中重复的has_emergency_lane信号；2、在EHRV2_SEGMENT_INFO_BUS中增加road_class和road_form_of_way信号。 | H23: merged | I23: merged
C24: 王亚伟 | D24: 20240704 | G24: 根据数据回传要求在PSM_DATACLCT_BUS增加回传信号 | H24: merged | I24: merged
C25: 杨克强 | D25: 2024071 | G25: 1.ICAS_STATE_BUS新增DAI_ModeDisp信号 2.ICAS_HMI_BUS新增DAI_ModeDisp信号 3.HMI_GENERAL_INFO_BUS新增DAI_Status信号 4.HMI模块新增VAL_DRIVER_DRIVE接口 | H25: merged | I25: merged
C26: 程振宁 | D26: 20240711 | G26: 删除fsm，FSM_FuncStatus改名为TOP_FuncStatus | H26: merged | I26: merged
C27: 朱莫武 | D27: 20240801 | G27: 新增sm模块 | H27: merged | I27: merged
C28: 王朝辉 | D28: 20240802 | G28: 新增信号 1.EHRV2_HEADER_BUS lanetracker输出信号 2.VEHICLE_SENSOR_INFO_BUS DR输入信号 3.MapFusionLoc_BUS DR输出信号/lanetracker输入信号 4.MapTopologyInfo_BUS lanetracker输入信号 | H28: merged | I28: merged
C29: 朱秋娴 | D29: 20240805 | G29: 新增各模块与SM交互接口，修改表格格式问题 | H29: merged | I29: merged
C30: 朱莫武 | D30: 20240806 | G30: 1、添加 SM_CORE_INFO SM_TASK_INFO SM_STATUS三个结构体数据类型 2、autosar_swc_sm模块添加SM_status output port | H30: merged | I30: merged
C31: 朱莫武 | D31: 20240812 | G31: 1、SM_HEART_BEAT_INFO 添加swc_id成员 | H31: merged | I31: merged
C32: 李杭 | D32: 20240813 | G32: 新增信号 1.TOS新增输出信号TOS_IE_Nudge、TOS_JunctionExist 2.LATP新增输入信号TOS_IE_Nudge、TOS_JunctionExist | H32: merged | I32: merged
C33: 姜宝祥 | D33: 20240813 | G33: 新增接口： 1 TOS新增输入信号:VAL_J3_RM、VAL_J3_TFL、PSM_STATE、ICAS_STATE、VAL_DRIVER_SWITCH、VAL_DRIVER_SWITCH | H33: merged | I33: merged
... C92: 王虎 | D92: 20241224 | G92: 1.根据DFIM模块增加ISLI_err / EBA_err接口 | H92: merged | I92: merged
C93: 杨克强 | D93: 20241224 | G93: 由于UDP落盘带宽问题 1.调整E01的someIP接口LaneLineList_2结构简化为8； 2.调整E01的someIP接口LaneLineList及其结构体定义，删除，此内容在本项目不使用 3.调整E01的someIP接口DynamicObjectList结构简化为10维； 4.调整E01的someIP接口StaticObjectList结构简化为10维； | H93: merged | I93: feature | J93: x
C94: 王虎 | D94: 20241225 | G94: 1.根据功能需求，DFIM模块增加FCTB_err / RCTB_err / FDM_err接口 | H94: merged | I94: feature
C95: 杨克强 | D95: 20241230 | G95: 由于spi通讯带宽问题 1.SomeIP_LaneLine_2_BUS删除型点和预留信息[LinePointList][LaneLineReserved] | H95: merged | I95: feature
C96: 程振宁 | D96: 20241230 | G96: 修复EVM_TSR_SPL_BUS.Map_Ramp_SPL维度为1维 | H96: merged | I96: feature
C97: 杨克强 | D97: 20241230 | G97: 新增VAL输出VAL_ICC_NAV接口，新增RLGS输入VAL_ICC_NAV接口 | H97: merged | I97: feature
C98: 王程 | D98: 20240103 | G98: 1 AEB_BRKINFO_BUS新增DWReq接口，用于近距离报警 2 AEB_FUSAIN_BUS的AEBAebTarID，AebTarCamID数据类型转换 3 AEB_TAROBJ_BUS增加接口用于观测 | H98: merged | I98: feature
C99: 谢新天 | D99: 20240103 | G99: HMI_GENERAL_INFO_BUS新增DW_Status接口 | H99: merged | I99: feature
C100: 程振宁 | D100: 20240106 | G100: AEB LSS增加 VAL功能安全状态接口，适配功能安全需求 | H100: merged | I100: feature
C101: 朱秋娴 | D101: 20240110 | G101: dataclct拆分出AEB_20ms_Data接口，新增VAL_SAF_TrigSftyAct接口 | H101: merged | I101: locked
C102: 朱秋娴 | D102: 20240115 | G102: Trigger_Data_BUS中新增VehSpdKph | H102: locked | I102: locked
...

Sheet Interface_Platform
A1: SWCName | B1: I/O | C1: PortType | D1: PortName/Operation | E1: Rte_Type/Return_Type | F1: RteTypeExist | G1: Description | H1: DataAccessMode | I1: IsQueued | J1: QueueLength | K1: InterfaceType | L1: IsService | M1: IsUpdated | N1: SignalType_Simple_Array_Record_ | O1: RecordTypedefName
A2: autosar_swc_dfim | B2: Outport | C2: S/R | D2: DFIM_FUNC_ERR | E2: DFIM_FUNC_ERR_BUS | F2: =IF(AND(ISNA(VLOOKUP(E2,DataType_Platform!A:A,1,FALSE())),ISNA(VLOOKUP(E2,BaseType!A:A,1,FALSE()))),"N","Y") -> Y | H2: Explict | I2: N
A3: autosar_swc_val | B3: Inport | C3: S/R | D3: StbM_TimeStamp | E3: StbM_TimeStampExtendedType | F3: =IF(AND(ISNA(VLOOKUP(E3,DataType_Platform!A:A,1,FALSE())),ISNA(VLOOKUP(E3,BaseType!A:A,1,FALSE()))),"N","Y") -> Y | H3: Explict | I3: N
A4: autosar_swc_val | B4: Inport | C4: S/R | D4: ADASFuncConfig | E4: FuncConfig_BUS | F4: =IF(AND(ISNA(VLOOKUP(E4,DataType_Platform!A:A,1,FALSE())),ISNA(VLOOKUP(E4,BaseType!A:A,1,FALSE()))),"N","Y") -> Y | H4: Explict | I4: N | M4: N
A5: autosar_swc_val | B5: Inport | C5: S/R | D5: TOP_FuncStatus | E5: uint8 | F5: =IF(AND(ISNA(VLOOKUP(E5,DataType_Platform!A:A,1,FALSE())),ISNA(VLOOKUP(E5,BaseType!A:A,1,FALSE()))),"N","Y") -> Y | H5: Explict | I5: N | K5: 0 | L5: 0 | M5: N | N5: 0 | O5: 0
A6: autosar_swc_val | B6: Inport | C6: S/R | D6: LAS_STATE | E6: LAS_STATE_BUS | F6: =IF(AND(ISNA(VLOOKUP(E6,DataType_Platform!A:A,1,FALSE())),ISNA(VLOOKUP(E6,BaseType!A:A,1,FALSE()))),"N","Y") -> Y | H6: Explict | I6: N | M6: N
A7: autosar_swc_val | B7: Inport | C7: S/R | D7: LAS_HMI | E7: LAS_HMI_BUS | F7: =IF(AND(ISNA(VLOOKUP(E7,DataType_Platform!A:A,1,FALSE())),ISNA(VLOOKUP(E7,BaseType!A:A,1,FALSE()))),"N","Y") -> Y | H7: Explict | I7: N | M7: N
A8: autosar_swc_val | B8: Inport | C8: S/R | D8: VMP_STS | E8: VMP_STS_BUS | F8: =IF(AND(ISNA(VLOOKUP(E8,DataType_Platform!A:A,1,FALSE())),ISNA(VLOOKUP(E8,BaseType!A:A,1,FALSE()))),"N","Y") -> Y | H8: Explict | I8: N | K8: 0 | L8: 0 | M8: N | N8: 0 | O8: 0
A9: autosar_swc_val | B9: Inport | C9: S/R | D9: LATP_HMI | E9: LATP_HMI_BUS | F9: =IF(AND(ISNA(VLOOKUP(E9,DataType_Platform!A:A,1,FALSE())),ISNA(VLOOKUP(E9,BaseType!A:A,1,FALSE()))),"N","Y") -> Y | H9: Explict | I9: N | M9: N
A10: autosar_swc_val | B10: Inport | C10: S/R | D10: VMC_LGT | E10: VMC_LGT_BUS | F10: =IF(AND(ISNA(VLOOKUP(E10,DataType_Platform!A:A,1,FALSE())),ISNA(VLOOKUP(E10,BaseType!A:A,1,FALSE()))),"N","Y") -> Y | H10: Explict | I10: N | M10: N
A11: autosar_swc_val | B11: Inport | C11: S/R | D11: VMC_LAT | E11: VMC_LAT_BUS | F11: =IF(AND(ISNA(VLOOKUP(E11,DataType_Platform!A:A,1,FALSE())),ISNA(VLOOKUP(E11,BaseType!A:A,1,FALSE()))),"N","Y") -> Y | H11: Explict | I11: N
A12: autosar_swc_val | B12: Inport | C12: S/R | D12: ICAS_STATE | E12: ICAS_STATE_BUS | F12: =IF(AND(ISNA(VLOOKUP(E12,DataType_Platform!A:A,1,FALSE())),ISNA(VLOOKUP(E12,BaseType!A:A,1,FALSE()))),"N","Y") -> Y | H12: Explict | I12: N | K12: 0 | L12: 0 | M12: N | N12: 0 | O12: 0
A13: autosar_swc_val | B13: Inport | C13: S/R | D13: ICAS_HMI | E13: ICAS_HMI_BUS | F13: =IF(AND(ISNA(VLOOKUP(E13,DataType_Platform!A:A,1,FALSE())),ISNA(VLOOKUP(E13,BaseType!A:A,1,FALSE()))),"N","Y") -> Y | H13: Explict | I13: N | M13: N
A14: autosar_swc_val | B14: Inport | C14: S/R | D14: AEB_BRKINFO | E14: AEB_BRKINFO_BUS | F14: =IF(AND(ISNA(VLOOKUP(E14,DataType_Platform!A:A,1,FALSE())),ISNA(VLOOKUP(E14,BaseType!A:A,1,FALSE()))),"N","Y") -> Y | H14: Explict | I14: N | M14: N
A15: autosar_swc_val | B15: Inport | C15: S/R | D15: AEB_TAROBJ | E15: AEB_TAROBJ_BUS | F15: =IF(AND(ISNA(VLOOKUP(E15,DataType_Platform!A:A,1,FALSE())),ISNA(VLOOKUP(E15,BaseType!A:A,1,FALSE()))),"N","Y") -> Y | H15: Explict | I15: N
A16: autosar_swc_val | B16: Inport | C16: S/R | D16: CSM_TSR_HMI | E16: TSR_HMI_BUS | F16: =IF(AND(ISNA(VLOOKUP(E16,DataType_Platform!A:A,1,FALSE())),ISNA(VLOOKUP(E16,BaseType!A:A,1,FALSE()))),"N","Y") -> Y | H16: Explict | I16: N | M16: N
A17: autosar_swc_val | B17: Inport | C17: S/R | D17: HMI_GENERAL_INFO | E17: HMI_GENERAL_INFO_BUS | F17: =IF(AND(ISNA(VLOOKUP(E17,DataType_Platform!A:A,1,FALSE())),ISNA(VLOOKUP(E17,BaseType!A:A,1,FALSE()))),"N","Y") -> Y | H17: Explict | I17: N | M17: N
A18: autosar_swc_val | B18: Inport | C18: S/R | D18: HMI_LANE | E18: rt_Array_HMI_LANE_BUS_8 | F18: =IF(AND(ISNA(VLOOKUP(E18,DataType_Platform!A:A,1,FALSE())),ISNA(VLOOKUP(E18,BaseType!A:A,1,FALSE()))),"N","Y") -> Y | H18: Explict | I18: N | M18: N
A19: autosar_swc_val | B19: Inport | C19: S/R | D19: HMI_OBJECT | E19: rt_Array_HMI_OBJECT_BUS_10 | F19: =IF(AND(ISNA(VLOOKUP(E19,DataType_Platform!A:A,1,FALSE())),ISNA(VLOOKUP(E19,BaseType!A:A,1,FALSE()))),"N","Y") -> Y | H19: Explict | I19: N | M19: N
A20: autosar_swc_val | B20: Inport | C20: S/R | D20: HMI_Light_Req | E20: HMI_Light_Req_MSG_BUS | F20: =IF(AND(ISNA(VLOOKUP(E20,DataType_Platform!A:A,1,FALSE())),ISNA(VLOOKUP(E20,BaseType!A:A,1,FALSE()))),"N","Y") -> Y | H20: Explict | I20: N | M20: N
A21: autosar_swc_val | B21: Inport | C21: S/R | D21: VAL_MemSet_SteerAngOffsetInit | E21: single | F21: =IF(AND(ISNA(VLOOKUP(E21,DataType_Platform!A:A,1,FALSE())),ISNA(VLOOKUP(E21,BaseType!A:A,1,FALSE()))),"N","Y") -> Y | H21: Explict | I21: N | K21: 0 | L21: 0 | M21: N | N21: 0 | O21: 0
A22: autosar_swc_val | B22: Inport | C22: S/R | D22: VAL_MemSet_TSRInit | E22: TSR_INIT_BUS | F22: =IF(AND(ISNA(VLOOKUP(E22,DataType_Platform!A:A,1,FALSE())),ISNA(VLOOKUP(E22,BaseType!A:A,1,FALSE()))),"N","Y") -> Y | H22: Explict | I22: N | K22: 0 | L22: 0 | M22: N | N22: 0 | O22: 0
A23: autosar_swc_val | B23: Inport | C23: S/R | D23: VAL_MemSet_TimeGapInit | E23: uint8 | F23: =IF(AND(ISNA(VLOOKUP(E23,DataType_Platform!A:A,1,FALSE())),ISNA(VLOOKUP(E23,BaseType!A:A,1,FALSE()))),"N","Y") -> Y | H23: Explict | I23: N | K23: 0 | L23: 0 | M23: N | N23: 0 | O23: 0
A24: autosar_swc_val | B24: Inport | C24: S/R | D24: VAL_MemSet_ACCStsInit | E24: uint8 | F24: =IF(AND(ISNA(VLOOKUP(E24,DataType_Platform!A:A,1,FALSE())),ISNA(VLOOKUP(E24,BaseType!A:A,1,FALSE()))),"N","Y") -> Y | H24: Explict | I24: N | K24: 0 | L24: 0 | M24: N | N24: 0 | O24: 0
A25: autosar_swc_val | B25: Inport | C25: S/R | D25: VAL_MemSet_ICASStsInit | E25: uint8 | F25: =IF(AND(ISNA(VLOOKUP(E25,DataType_Platform!A:A,1,FALSE())),ISNA(VLOOKUP(E25,BaseType!A:A,1,FALSE()))),"N","Y") -> Y | H25: Explict | I25: N | K25: 0 | L25: 0 | M25: N | N25: 0 | O25: 0
A26: autosar_swc_val | B26: Inport | C26: S/R | D26: SysIn_NvM_Read | E26: NvM_ACCESS_BUS | F26: =IF(AND(ISNA(VLOOKUP(E26,DataType_Platform!A:A,1,FALSE())),ISNA(VLOOKUP(E26,BaseType!A:A,1,FALSE()))),"N","Y") -> Y | H26: Explict | I26: N | M26: N
A27: autosar_swc_val | B27: Inport | C27: S/R | D27: J3_LANE | E27: J3_LANE_BUS | F27: =IF(AND(ISNA(VLOOKUP(E27,DataType_Platform!A:A,1,FALSE())),ISNA(VLOOKUP(E27,BaseType!A:A,1,FALSE()))),"N","Y") -> Y | H27: Explict | I27: N
A28: autosar_swc_val | B28: Inport | C28: S/R | D28: FM_SAF_OUT | E28: FM_SAF_OUT_BUS | F28: =IF(AND(ISNA(VLOOKUP(E28,DataType_Platform!A:A,1,FALSE())),ISNA(VLOOKUP(E28,BaseType!A:A,1,FALSE()))),"N","Y") -> Y | G28: 功能安全指令 | H28: Explict | I28: N
A29: autosar_swc_val | B29: Inport | C29: C/S | D29: Val_WdgMAliveCall() | E29: Std_ReturnType | F29: =IF(AND(ISNA(VLOOKUP(E29,DataType_Platform!A:A,1,FALSE())),ISNA(VLOOKUP(E29,BaseType!A:A,1,FALSE()))),"N","Y") -> Y | G29: 程序流-存活点 | H29: Sync | I29: N | L29: N
A30: autosar_swc_val | B30: Inport | C30: C/S | D30: Val_WdgMDdlStartCall() | E30: Std_ReturnType | F30: =IF(AND(ISNA(VLOOKUP(E30,DataType_Platform!A:A,1,FALSE())),ISNA(VLOOKUP(E30,BaseType!A:A,1,FALSE()))),"N","Y") -> Y | G30: 程序流-期限起点 | H30: Sync | I30: N | L30: N
A31: autosar_swc_val | B31: Inport | C31: C/S | D31: Val_WdgMDdlStopCall() | E31: Std_ReturnType | F31: =IF(AND(ISNA(VLOOKUP(E31,DataType_Platform!A:A,1,FALSE())),ISNA(VLOOKUP(E31,BaseType!A:A,1,FALSE()))),"N","Y") -> Y | G31: 程序流-期限终点 | H31: Sync | I31: N | L31: N
A32: autosar_swc_val | B32: Outport | C32: S/R | D32: VAL_Heartbeat_Info | E32: SM_HEART_BEAT_INFO | F32: =IF(AND(ISNA(VLOOKUP(E32,DataType_Platform!A:A,1,FALSE())),ISNA(VLOOKUP(E32,BaseType!A:A,1,FALSE()))),"N","Y") -> Y | H32: Explict | I32: N | K32: 0 | L32: 0 | M32: N | N32: 0 | O32: 0
A33: autosar_swc_val | B33: Outport | C33: S/R | D33: VAL_DRIVER_SWITCH | E33: VAL_DRIVER_SWITCH_BUS | F33: =IF(AND(ISNA(VLOOKUP(E33,DataType_Platform!A:A,1,FALSE())),ISNA(VLOOKUP(E33,BaseType!A:A,1,FALSE()))),"N","Y") -> Y | H33: Explict | I33: N | K33: 0 | L33: 0 | M33: N | N33: 0 | O33: 0
A34: autosar_swc_val | B34: Outport | C34: S/R | D34: VAL_DRIVER_DRIVE | E34: VAL_DRIVER_DRIVE_BUS | F34: =IF(AND(ISNA(VLOOKUP(E34,DataType_Platform!A:A,1,FALSE())),ISNA(VLOOKUP(E34,BaseType!A:A,1,FALSE()))),"N","Y") -> Y | H34: Explict | I34: N | K34: 0 | L34: 0 | M34: N | N34: 0 | O34: 0
A35: autosar_swc_val | B35: Outport | C35: S/R | D35: VAL_DRIVER_STATE | E35: VAL_DRIVER_STATE_BUS | F35: =IF(AND(ISNA(VLOOKUP(E35,DataType_Platform!A:A,1,FALSE())),ISNA(VLOOKUP(E35,BaseType!A:A,1,FALSE()))),"N","Y") -> Y | H35: Explict | I35: N | K35: 0 | L35: 0 | M35: N | N35: 0 | O35: 0
A36: autosar_swc_val | B36: Outport | C36: S/R | D36: VAL_VEHICLE_STATE | E36: VAL_VEHICLE_STATE_BUS | F36: =IF(AND(ISNA(VLOOKUP(E36,DataType_Platform!A:A,1,FALSE())),ISNA(VLOOKUP(E36,BaseType!A:A,1,FALSE()))),"N","Y") -> Y | H36: Explict | I36: N | K36: 0 | L36: 0 | M36: N | N36: 0 | O36: 0
A37: autosar_swc_val | B37: Outport | C37: S/R | D37: VAL_VEHICLE_FUNC | E37: VAL_VEHICLE_FUNC_BUS | F37: =IF(AND(ISNA(VLOOKUP(E37,DataType_Platform!A:A,1,FALSE())),ISNA(VLOOKUP(E37,BaseType!A:A,1,FALSE()))),"N","Y") -> Y | H37: Explict | I37: N | K37: 0 | L37: 0 | M37: N | N37: 0 | O37: 0
A38: autosar_swc_val | B38: Outport | C38: S/R | D38: VAL_VEHICLE_PARTS | E38: VAL_VEHICLE_PARTS_BUS | F38: =IF(AND(ISNA(VLOOKUP(E38,DataType_Platform!A:A,1,FALSE())),ISNA(VLOOKUP(E38,BaseType!A:A,1,FALSE()))),"N","Y") -> Y | H38: Explict | I38: N | K38: 0 | L38: 0 | M38: N | N38: 0 | O38: 0
A39: autosar_swc_val | B39: Outport | C39: S/R | D39: VAL_ENV | E39: VAL_ENV_BUS | F39: =IF(AND(ISNA(VLOOKUP(E39,DataType_Platform!A:A,1,FALSE())),ISNA(VLOOKUP(E39,BaseType!A:A,1,FALSE()))),"N","Y") -> Y | H39: Explict | I39: N | K39: 0 | L39: 0 | M39: N | N39: 0 | O39: 0
A40: autosar_swc_val | B40: Outport | C40: S/R | D40: VAL_CONFIG | E40: VAL_CONFIG_BUS | F40: =IF(AND(ISNA(VLOOKUP(E40,DataType_Platform!A:A,1,FALSE())),ISNA(VLOOKUP(E40,BaseType!A:A,1,FALSE()))),"N","Y") -> Y | H40: Explict | I40: N | K40: 0 | L40: 0 | M40: N | N40: 0 | O40: 0
...

Sheet DataType_Platform
A1: Data Type Name | B1: IsUsed | C1: Member(valid if Data Type is Struct or Enum) | D1: DataType/EnumValue | E1: Dimensions | F1: Data Type Exist | G1: Description | H1: Size(bits) | I1: Min | J1: Max | K1: Factor | L1: Offset | M1: Unit
A2: ICAS_HMI_BUS | B2: =IF(ISBLANK(A2),"",IF(AND(ISNA(VLOOKUP(A2,Interface_Platform!E:E,1,FALSE())),ISNA(VLOOKUP(A2,D:D,1,FALSE()))),"N","Y")) -> Y | D2: Struct | F2: =IF(AND(ISNA(VLOOKUP(D2,A:A,1,FALSE())),ISNA(VLOOKUP(D2,BaseType!A:A,1,FALSE())),D2<>"Struct"),"N","Y") -> Y | H2: 0 | I2: 0 | J2: 0 | K2: 0 | L2: 0 | M2: 0
B3: =IF(ISBLANK(A3),"",IF(AND(ISNA(VLOOKUP(A3,Interface_Platform!E:E,1,FALSE())),ISNA(VLOOKUP(A3,D:D,1,FALSE()))),"N","Y")) | C3: EcallReq | D3: boolean | E3: 1 | F3: =IF(AND(ISNA(VLOOKUP(D3,A:A,1,FALSE())),ISNA(VLOOKUP(D3,BaseType!A:A,1,FALSE())),D3<>"Struct"),"N","Y") -> Y | H3: 0 | I3: 0 | J3: 0 | K3: 0 | L3: 0 | M3: 0
B4: =IF(ISBLANK(A4),"",IF(AND(ISNA(VLOOKUP(A4,Interface_Platform!E:E,1,FALSE())),ISNA(VLOOKUP(A4,D:D,1,FALSE()))),"N","Y")) | C4: ParkShiftReq | D4: boolean | E4: 1 | F4: =IF(AND(ISNA(VLOOKUP(D4,A:A,1,FALSE())),ISNA(VLOOKUP(D4,BaseType!A:A,1,FALSE())),D4<>"Struct"),"N","Y") -> Y | H4: 0 | I4: 0 | J4: 0 | K4: 0 | L4: 0 | M4: 0
B5: =IF(ISBLANK(A5),"",IF(AND(ISNA(VLOOKUP(A5,Interface_Platform!E:E,1,FALSE())),ISNA(VLOOKUP(A5,D:D,1,FALSE()))),"N","Y")) | C5: ACC_ModDisp | D5: uint8 | E5: 1 | F5: =IF(AND(ISNA(VLOOKUP(D5,A:A,1,FALSE())),ISNA(VLOOKUP(D5,BaseType!A:A,1,FALSE())),D5<>"Struct"),"N","Y") -> Y | G5: 0:off 1:passive 2:ready 3:active 4:brakeonly 5:override 6:standwait 7:failure 8:comfort exit 9:standactive | H5: 0 | I5: 0 | J5: 0 | K5: 0 | L5: 0 | M5: 0
B6: =IF(ISBLANK(A6),"",IF(AND(ISNA(VLOOKUP(A6,Interface_Platform!E:E,1,FALSE())),ISNA(VLOOKUP(A6,D:D,1,FALSE()))),"N","Y")) | C6: LCC_ModeDisp | D6: uint8 | E6: 1 | F6: =IF(AND(ISNA(VLOOKUP(D6,A:A,1,FALSE())),ISNA(VLOOKUP(D6,BaseType!A:A,1,FALSE())),D6<>"Struct"),"N","Y") -> Y | G6: 0:off 1:passive 2:ready 3:active 6:wait 7:failure 9:safestop 11:mrc | H6: 0 | I6: 0 | J6: 0 | K6: 0 | L6: 0 | M6: 0
C7: ALC_ModeDisp | D7: uint8 | E7: 1 | F7: =IF(AND(ISNA(VLOOKUP(D7,A:A,1,FALSE())),ISNA(VLOOKUP(D7,BaseType!A:A,1,FALSE())),D7<>"Struct"),"N","Y") -> Y | G7: 0:passive 1:ready 2:confirmle 3:confirmri 4:leftchanging 5rightchanging 8:failure
C8: NOA_ModeDisp | D8: uint8 | E8: 1 | F8: =IF(AND(ISNA(VLOOKUP(D8,A:A,1,FALSE())),ISNA(VLOOKUP(D8,BaseType!A:A,1,FALSE())),D8<>"Struct"),"N","Y") -> Y | G8: 0off/1idle/2ready/3active/7failure
C9: DAI_ModeDisp | D9: uint8 | E9: 1 | F9: =IF(AND(ISNA(VLOOKUP(D9,A:A,1,FALSE())),ISNA(VLOOKUP(D9,BaseType!A:A,1,FALSE())),D9<>"Struct"),"N","Y") -> Y | G9: 0x0=Initial;0x1=Off;0x2=Passive;0x3=Standby;0x4=Active;0x7=Failure
C10: Nudge_ModeDisp | D10: uint8 | E10: 1 | F10: =IF(AND(ISNA(VLOOKUP(D10,A:A,1,FALSE())),ISNA(VLOOKUP(D10,BaseType!A:A,1,FALSE())),D10<>"Struct"),"N","Y") -> Y | G10: 1:off 2:passive 3:ready 4:left 5:right
C11: IHBC_ModeDisp | D11: uint8 | E11: 1 | F11: =IF(AND(ISNA(VLOOKUP(D11,A:A,1,FALSE())),ISNA(VLOOKUP(D11,BaseType!A:A,1,FALSE())),D11<>"Struct"),"N","Y") -> Y | G11: 0:off 1:standby 2:active 3:failure
C12: HighLowBeamReq | D12: uint8 | E12: 1 | F12: =IF(AND(ISNA(VLOOKUP(D12,A:A,1,FALSE())),ISNA(VLOOKUP(D12,BaseType!A:A,1,FALSE())),D12<>"Struct"),"N","Y") -> Y | G12: 1 req
B13: =IF(ISBLANK(A13),"",IF(AND(ISNA(VLOOKUP(A13,Interface_Platform!E:E,1,FALSE())),ISNA(VLOOKUP(A13,D:D,1,FALSE()))),"N","Y")) | C13: InfoDispHMI | D13: uint8 | E13: 2 | F13: =IF(AND(ISNA(VLOOKUP(D13,A:A,1,FALSE())),ISNA(VLOOKUP(D13,BaseType!A:A,1,FALSE())),D13<>"Struct"),"N","Y") -> Y | G13: 第一维作为ACC、LCC 第二维用作NOA、ALC | H13: 0 | I13: 0 | J13: 0 | K13: 0 | L13: 0 | M13: 0
B14: =IF(ISBLANK(A14),"",IF(AND(ISNA(VLOOKUP(A14,Interface_Platform!E:E,1,FALSE())),ISNA(VLOOKUP(A14,D:D,1,FALSE()))),"N","Y")) | C14: HazActv | D14: uint8 | E14: 1 | F14: =IF(AND(ISNA(VLOOKUP(D14,A:A,1,FALSE())),ISNA(VLOOKUP(D14,BaseType!A:A,1,FALSE())),D14<>"Struct"),"N","Y") -> Y | G14: 1 aeb 双闪 2 MRM双闪 | H14: 0 | I14: 0 | J14: 0 | K14: 0 | L14: 0 | M14: 0
B15: =IF(ISBLANK(A15),"",IF(AND(ISNA(VLOOKUP(A15,Interface_Platform!E:E,1,FALSE())),ISNA(VLOOKUP(A15,D:D,1,FALSE()))),"N","Y")) | C15: TurnLampReq | D15: uint8 | E15: 1 | F15: =IF(AND(ISNA(VLOOKUP(D15,A:A,1,FALSE())),ISNA(VLOOKUP(D15,BaseType!A:A,1,FALSE())),D15<>"Struct"),"N","Y") -> Y | H15: 0 | I15: 0 | J15: 0 | K15: 0 | L15: 0 | M15: 0
B16: =IF(ISBLANK(A16),"",IF(AND(ISNA(VLOOKUP(A16,Interface_Platform!E:E,1,FALSE())),ISNA(VLOOKUP(A16,D:D,1,FALSE()))),"N","Y")) | C16: DriveOffDisp | D16: uint8 | E16: 1 | F16: =IF(AND(ISNA(VLOOKUP(D16,A:A,1,FALSE())),ISNA(VLOOKUP(D16,BaseType!A:A,1,FALSE())),D16<>"Struct"),"N","Y") -> Y | G16: 0x0:no request 0x1:The front car has started 0x2:The front car has started,Please pay attention to the road environmentahead 0x3:The front car has started,please keep your attention 0x4:The front car has started,please take over the car | H16: 0 | I16: 0 | J16: 0 | K16: 0 | L16: 0 | M16: 0
B17: =IF(ISBLANK(A17),"",IF(AND(ISNA(VLOOKUP(A17,Interface_Platform!E:E,1,FALSE())),ISNA(VLOOKUP(A17,D:D,1,FALSE()))),"N","Y")) | C17: HandsOffWarningLevel | D17: uint8 | E17: 1 | F17: =IF(AND(ISNA(VLOOKUP(D17,A:A,1,FALSE())),ISNA(VLOOKUP(D17,BaseType!A:A,1,FALSE())),D17<>"Struct"),"N","Y") -> Y | G17: 脱手计时等级1一级2二级3三级4safestop | H17: 0 | I17: 0 | J17: 0 | K17: 0 | L17: 0 | M17: 0
B18: =IF(ISBLANK(A18),"",IF(AND(ISNA(VLOOKUP(A18,Interface_Platform!E:E,1,FALSE())),ISNA(VLOOKUP(A18,D:D,1,FALSE()))),"N","Y")) | C18: DriverInloopMonitor | D18: uint8 | E18: 1 | F18: =IF(AND(ISNA(VLOOKUP(D18,A:A,1,FALSE())),ISNA(VLOOKUP(D18,BaseType!A:A,1,FALSE())),D18<>"Struct"),"N","Y") -> Y | H18: 0 | I18: 0 | J18: 0 | K18: 0 | L18: 0 | M18: 0
B19: =IF(ISBLANK(A19),"",IF(AND(ISNA(VLOOKUP(A19,Interface_Platform!E:E,1,FALSE())),ISNA(VLOOKUP(A19,D:D,1,FALSE()))),"N","Y")) | C19: WarningLevel | D19: uint8 | E19: 1 | F19: =IF(AND(ISNA(VLOOKUP(D19,A:A,1,FALSE())),ISNA(VLOOKUP(D19,BaseType!A:A,1,FALSE())),D19<>"Struct"),"N","Y") -> Y | G19: 这个是HWA的脱手等级输出，用于HMI | H19: 0 | I19: 0 | J19: 0 | K19: 0 | L19: 0 | M19: 0
A20: CSC_CTRL_BUS | B20: =IF(ISBLANK(A20),"",IF(AND(ISNA(VLOOKUP(A20,Interface_Platform!E:E,1,FALSE())),ISNA(VLOOKUP(A20,D:D,1,FALSE()))),"N","Y")) -> Y | D20: Struct | F20: =IF(AND(ISNA(VLOOKUP(D20,A:A,1,FALSE())),ISNA(VLOOKUP(D20,BaseType!A:A,1,FALSE())),D20<>"Struct"),"N","Y") -> Y | H20: 0 | I20: 0 | J20: 0 | K20: 0 | L20: 0 | M20: 0
B21: =IF(ISBLANK(A21),"",IF(AND(ISNA(VLOOKUP(A21,Interface_Platform!E:E,1,FALSE())),ISNA(VLOOKUP(A21,D:D,1,FALSE()))),"N","Y")) | C21: VsetBelowMin | D21: boolean | E21: 1 | F21: =IF(AND(ISNA(VLOOKUP(D21,A:A,1,FALSE())),ISNA(VLOOKUP(D21,BaseType!A:A,1,FALSE())),D21<>"Struct"),"N","Y") -> Y | H21: 0 | I21: 0 | J21: 0 | K21: 0 | L21: 0 | M21: 0
B22: =IF(ISBLANK(A22),"",IF(AND(ISNA(VLOOKUP(A22,Interface_Platform!E:E,1,FALSE())),ISNA(VLOOKUP(A22,D:D,1,FALSE()))),"N","Y")) | C22: CruiseSpdCtrlLevel | D22: uint8 | E22: 1 | F22: =IF(AND(ISNA(VLOOKUP(D22,A:A,1,FALSE())),ISNA(VLOOKUP(D22,BaseType!A:A,1,FALSE())),D22<>"Struct"),"N","Y") -> Y | H22: 0 | I22: 0 | J22: 0 | K22: 0 | L22: 0 | M22: 0
B23: =IF(ISBLANK(A23),"",IF(AND(ISNA(VLOOKUP(A23,Interface_Platform!E:E,1,FALSE())),ISNA(VLOOKUP(A23,D:D,1,FALSE()))),"N","Y")) | C23: TimeGapLevel | D23: uint8 | E23: 1 | F23: =IF(AND(ISNA(VLOOKUP(D23,A:A,1,FALSE())),ISNA(VLOOKUP(D23,BaseType!A:A,1,FALSE())),D23<>"Struct"),"N","Y") -> Y | H23: 0 | I23: 0 | J23: 0 | K23: 0 | L23: 0 | M23: 0
B24: =IF(ISBLANK(A24),"",IF(AND(ISNA(VLOOKUP(A24,Interface_Platform!E:E,1,FALSE())),ISNA(VLOOKUP(A24,D:D,1,FALSE()))),"N","Y")) | C24: CruiseSpdKmh | D24: single | E24: 1 | F24: =IF(AND(ISNA(VLOOKUP(D24,A:A,1,FALSE())),ISNA(VLOOKUP(D24,BaseType!A:A,1,FALSE())),D24<>"Struct"),"N","Y") -> Y | H24: 0 | I24: 0 | J24: 0 | K24: 0 | L24: 0 | M24: 0
B25: =IF(ISBLANK(A25),"",IF(AND(ISNA(VLOOKUP(A25,Interface_Platform!E:E,1,FALSE())),ISNA(VLOOKUP(A25,D:D,1,FALSE()))),"N","Y")) | C25: ISL_APSpdLimSPL | D25: single | E25: 1 | F25: =IF(AND(ISNA(VLOOKUP(D25,A:A,1,FALSE())),ISNA(VLOOKUP(D25,BaseType!A:A,1,FALSE())),D25<>"Struct"),"N","Y") -> Y | H25: 0 | I25: 0 | J25: 0 | K25: 0 | L25: 0 | M25: 0
B26: =IF(ISBLANK(A26),"",IF(AND(ISNA(VLOOKUP(A26,Interface_Platform!E:E,1,FALSE())),ISNA(VLOOKUP(A26,D:D,1,FALSE()))),"N","Y")) | C26: ISL_APSpdLimDist | D26: single | E26: 1 | F26: =IF(AND(ISNA(VLOOKUP(D26,A:A,1,FALSE())),ISNA(VLOOKUP(D26,BaseType!A:A,1,FALSE())),D26<>"Struct"),"N","Y") -> Y | H26: 0 | I26: 0 | J26: 0 | K26: 0 | L26: 0 | M26: 0
A27: CSC_HMI_BUS | B27: =IF(ISBLANK(A27),"",IF(AND(ISNA(VLOOKUP(A27,Interface_Platform!E:E,1,FALSE())),ISNA(VLOOKUP(A27,D:D,1,FALSE()))),"N","Y")) -> Y | D27: Struct | F27: =IF(AND(ISNA(VLOOKUP(D27,A:A,1,FALSE())),ISNA(VLOOKUP(D27,BaseType!A:A,1,FALSE())),D27<>"Struct"),"N","Y") -> Y | H27: 0 | I27: 0 | J27: 0 | K27: 0 | L27: 0 | M27: 0
B28: =IF(ISBLANK(A28),"",IF(AND(ISNA(VLOOKUP(A28,Interface_Platform!E:E,1,FALSE())),ISNA(VLOOKUP(A28,D:D,1,FALSE()))),"N","Y")) | C28: CruiseSpdValueHMI | D28: uint8 | E28: 1 | F28: =IF(AND(ISNA(VLOOKUP(D28,A:A,1,FALSE())),ISNA(VLOOKUP(D28,BaseType!A:A,1,FALSE())),D28<>"Struct"),"N","Y") -> Y | H28: 0 | I28: 0 | J28: 0 | K28: 0 | L28: 0 | M28: 0
B29: =IF(ISBLANK(A29),"",IF(AND(ISNA(VLOOKUP(A29,Interface_Platform!E:E,1,FALSE())),ISNA(VLOOKUP(A29,D:D,1,FALSE()))),"N","Y")) | C29: TimeGapLevelHMI | D29: uint8 | E29: 1 | F29: =IF(AND(ISNA(VLOOKUP(D29,A:A,1,FALSE())),ISNA(VLOOKUP(D29,BaseType!A:A,1,FALSE())),D29<>"Struct"),"N","Y") -> Y | G29: HMI参考上升沿0:不显示 1:Level1 2:Level2 3:Level3 4:Level4 5:Level5 | H29: 0 | I29: 0 | J29: 0 | K29: 0 | L29: 0 | M29: 0
B30: =IF(ISBLANK(A30),"",IF(AND(ISNA(VLOOKUP(A30,Interface_Platform!E:E,1,FALSE())),ISNA(VLOOKUP(A30,D:D,1,FALSE()))),"N","Y")) | C30: InfoDispHMI | D30: uint8 | E30: 1 | F30: =IF(AND(ISNA(VLOOKUP(D30,A:A,1,FALSE())),ISNA(VLOOKUP(D30,BaseType!A:A,1,FALSE())),D30<>"Struct"),"N","Y") -> Y | G30: 0x1:SCF down 0x2:SCF up 0x3:CurvSPL | H30: 0 | I30: 0 | J30: 0 | K30: 0 | L30: 0 | M30: 0
C31: ISL_Sts | D31: uint8 | E31: 1 | F31: =IF(AND(ISNA(VLOOKUP(D31,A:A,1,FALSE())),ISNA(VLOOKUP(D31,BaseType!A:A,1,FALSE())),D31<>"Struct"),"N","Y") -> Y | G31: SCFSts：0x0=off;0x1=Standby/InformActive;0x2=SpeedAdjust;0x3=Failure
C32: ISL_SetSpdAdjReq | D32: uint8 | E32: 1 | F32: =IF(AND(ISNA(VLOOKUP(D32,A:A,1,FALSE())),ISNA(VLOOKUP(D32,BaseType!A:A,1,FALSE())),D32<>"Struct"),"N","Y") -> Y | G32: 0x1:SCF TipSound
C33: ISL_SetSpdAdjVal | D33: single | E33: 1 | F33: =IF(AND(ISNA(VLOOKUP(D33,A:A,1,FALSE())),ISNA(VLOOKUP(D33,BaseType!A:A,1,FALSE())),D33<>"Struct"),"N","Y") -> Y
C34: ISL_NOA_SPL_kph | D34: single | E34: 1 | F34: =IF(AND(ISNA(VLOOKUP(D34,A:A,1,FALSE())),ISNA(VLOOKUP(D34,BaseType!A:A,1,FALSE())),D34<>"Struct"),"N","Y") -> Y
C35: ISL_NOA_SPL_Distance2Split | D35: single | E35: 1 | F35: =IF(AND(ISNA(VLOOKUP(D35,A:A,1,FALSE())),ISNA(VLOOKUP(D35,BaseType!A:A,1,FALSE())),D35<>"Struct"),"N","Y") -> Y
C36: ISL_iAccLoLim_kph | D36: single | E36: 1 | F36: =IF(AND(ISNA(VLOOKUP(D36,A:A,1,FALSE())),ISNA(VLOOKUP(D36,BaseType!A:A,1,FALSE())),D36<>"Struct"),"N","Y") -> Y
C37: ISL_iAccHiLim_kph | D37: single | E37: 1 | F37: =IF(AND(ISNA(VLOOKUP(D37,A:A,1,FALSE())),ISNA(VLOOKUP(D37,BaseType!A:A,1,FALSE())),D37<>"Struct"),"N","Y") -> Y
A38: LONP_ACCPLAN_BUS | B38: =IF(ISBLANK(A38),"",IF(AND(ISNA(VLOOKUP(A38,Interface_Platform!E:E,1,FALSE())),ISNA(VLOOKUP(A38,D:D,1,FALSE()))),"N","Y")) -> Y | D38: Struct | F38: =IF(AND(ISNA(VLOOKUP(D38,A:A,1,FALSE())),ISNA(VLOOKUP(D38,BaseType!A:A,1,FALSE())),D38<>"Struct"),"N","Y") -> Y | H38: 0 | I38: 0 | J38: 0 | K38: 0 | L38: 0 | M38: 0
B39: =IF(ISBLANK(A39),"",IF(AND(ISNA(VLOOKUP(A39,Interface_Platform!E:E,1,FALSE())),ISNA(VLOOKUP(A39,D:D,1,FALSE()))),"N","Y")) | C39: ACC_BrakePrefer | D39: boolean | E39: 1 | F39: =IF(AND(ISNA(VLOOKUP(D39,A:A,1,FALSE())),ISNA(VLOOKUP(D39,BaseType!A:A,1,FALSE())),D39<>"Struct"),"N","Y") -> Y | G39: 制动优先标志位： 0-无制动优先； 1-制动优先 | H39: 0 | I39: 0 | J39: 0 | K39: 0 | L39: 0 | M39: 0
B40: =IF(ISBLANK(A40),"",IF(AND(ISNA(VLOOKUP(A40,Interface_Platform!E:E,1,FALSE())),ISNA(VLOOKUP(A40,D:D,1,FALSE()))),"N","Y")) | C40: ACC_axvCvAim | D40: single | E40: 1 | F40: =IF(AND(ISNA(VLOOKUP(D40,A:A,1,FALSE())),ISNA(VLOOKUP(D40,BaseType!A:A,1,FALSE())),D40<>"Struct"),"N","Y") -> Y | G40: 纵向加速度请求值 | H40: 0 | I40: 0 | J40: 0 | K40: 0 | L40: 0 | M40: 0
...

Sheet Interface_T1GC
A1: SWCName | B1: I/O | C1: PortType | D1: PortName/Operation | E1: Rte_Type/Return_Type | F1: RteTypeExist | G1: Description | H1: DataAccessMode | I1: IsQueued | J1: QueueLength | K1: InterfaceType | L1: IsService | M1: IsUpdated | N1: SignalType_Simple_Array_Record_ | O1: RecordTypedefName
A2: autosar_swc_val | B2: Outport | C2: S/R | D2: SysOut_ADASDisplayExtend | E2: SomeIP_ADASDisplayExtend_BUS | F2: =IF(AND(ISNA(VLOOKUP(E2,DataType_T1GC!A:A,1,FALSE())),ISNA(VLOOKUP(E2,BaseType!A:A,1,FALSE()))),"N","Y") -> Y | H2: Explict | I2: N | M2: N
A3: autosar_swc_val | B3: Outport | C3: S/R | D3: SysOut_ParkingGenaralInfo | E3: SomeIP_ParkingGenaralInfo_BUS | F3: =IF(AND(ISNA(VLOOKUP(E3,DataType_T1GC!A:A,1,FALSE())),ISNA(VLOOKUP(E3,BaseType!A:A,1,FALSE()))),"N","Y") -> Y | H3: Explict | I3: N | M3: N
A4: autosar_swc_val | B4: Outport | C4: S/R | D4: SysOut_FuncState_HD | E4: SomeIP_FuncState_HD_BUS | F4: =IF(AND(ISNA(VLOOKUP(E4,DataType_T1GC!A:A,1,FALSE())),ISNA(VLOOKUP(E4,BaseType!A:A,1,FALSE()))),"N","Y") -> Y | H4: Explict | I4: N | M4: N
A5: autosar_swc_val | B5: Inport | C5: S/R | D5: PR_APA_DA_IDCU_11_Tx | E5: APA_DA_IDCU_11_Tx_BUS | F5: =IF(AND(ISNA(VLOOKUP(E5,DataType_T1GC!A:A,1,FALSE())),ISNA(VLOOKUP(E5,BaseType!A:A,1,FALSE()))),"N","Y") -> Y | H5: Explict | I5: N | M5: N
A6: autosar_swc_val | B6: Inport | C6: S/R | D6: PR_APA_DA_IDCU_13_Tx | E6: APA_DA_IDCU_13_Tx_BUS | F6: =IF(AND(ISNA(VLOOKUP(E6,DataType_T1GC!A:A,1,FALSE())),ISNA(VLOOKUP(E6,BaseType!A:A,1,FALSE()))),"N","Y") -> Y | H6: Explict | I6: N | M6: N
A7: autosar_swc_val | B7: Inport | C7: S/R | D7: PR_APA_DA_IDCU_9_Tx | E7: APA_DA_IDCU_9_Tx_BUS | F7: =IF(AND(ISNA(VLOOKUP(E7,DataType_T1GC!A:A,1,FALSE())),ISNA(VLOOKUP(E7,BaseType!A:A,1,FALSE()))),"N","Y") -> Y | H7: Explict | I7: N | M7: N
A8: autosar_swc_val | B8: Inport | C8: S/R | D8: PR_APA_DA_FCM_FRM_1_Tx | E8: APA_DA_FCM_FRM_1_Tx_BUS | F8: =IF(AND(ISNA(VLOOKUP(E8,DataType_T1GC!A:A,1,FALSE())),ISNA(VLOOKUP(E8,BaseType!A:A,1,FALSE()))),"N","Y") -> Y | H8: Explict | I8: N | M8: N
A9: autosar_swc_val | B9: Inport | C9: S/R | D9: PR_APA_DA_FCM_FRM_2_Tx | E9: APA_DA_FCM_FRM_2_Tx_BUS | F9: =IF(AND(ISNA(VLOOKUP(E9,DataType_T1GC!A:A,1,FALSE())),ISNA(VLOOKUP(E9,BaseType!A:A,1,FALSE()))),"N","Y") -> Y | H9: Explict | I9: N | M9: N
A10: autosar_swc_val | B10: Inport | C10: S/R | D10: PR_APA_DA_FCM_FRM_6_Tx | E10: APA_DA_FCM_FRM_6_Tx_BUS | F10: =IF(AND(ISNA(VLOOKUP(E10,DataType_T1GC!A:A,1,FALSE())),ISNA(VLOOKUP(E10,BaseType!A:A,1,FALSE()))),"N","Y") -> Y | H10: Explict | I10: N | M10: N
A11: autosar_swc_val | B11: Inport | C11: S/R | D11: PR_APA_DA_RLCR_2_Tx | E11: APA_DA_RLCR_2_Tx_BUS | F11: =IF(AND(ISNA(VLOOKUP(E11,DataType_T1GC!A:A,1,FALSE())),ISNA(VLOOKUP(E11,BaseType!A:A,1,FALSE()))),"N","Y") -> Y | H11: Explict | I11: N | M11: N
A12: autosar_swc_val | B12: Inport | C12: S/R | D12: PR_APA_DA_AVM_APA_2_Tx | E12: APA_DA_AVM_APA_2_Tx_BUS | F12: =IF(AND(ISNA(VLOOKUP(E12,DataType_T1GC!A:A,1,FALSE())),ISNA(VLOOKUP(E12,BaseType!A:A,1,FALSE()))),"N","Y") -> Y | H12: Explict | I12: N | M12: N
A13: autosar_swc_val | B13: Inport | C13: S/R | D13: CORNER_RADAR_FL | E13: Corner_Radar_Array_Info | F13: =IF(AND(ISNA(VLOOKUP(E13,DataType_T1GC!A:A,1,FALSE())),ISNA(VLOOKUP(E13,BaseType!A:A,1,FALSE()))),"N","Y") -> Y | H13: Explict | I13: N | M13: N
... A20: autosar_swc_fusion | B20: Inport | C20: S/R | D20: CORNER_RADAR_RR | E20: Corner_Radar_Array_Info | F20: =IF(AND(ISNA(VLOOKUP(E20,DataType_T1GC!A:A,1,FALSE())),ISNA(VLOOKUP(E20,BaseType!A:A,1,FALSE()))),"N","Y") -> Y | H20: Explict | I20: N | M20: Y

Sheet DataType_T1GC
A1: Data Type Name | B1: IsUsed | C1: Member(valid if Data Type is Struct or Enum) | D1: DataType/EnumValue | E1: Dimensions | F1: Data Type Exist | G1: Description | H1: Size(bits) | I1: Min | J1: Max | K1: Factor | L1: Offset | M1: Unit
A2: SomeIP_ADASDisplayExtend_BUS | B2: =IF(ISBLANK(A2),"",IF(AND(ISNA(VLOOKUP(A2,Interface_T1GC!E:E,1,FALSE())),ISNA(VLOOKUP(A2,D:D,1,FALSE()))),"N","Y")) -> Y | D2: Struct | F2: =IF(AND(ISNA(VLOOKUP(D2,A:A,1,FALSE())),ISNA(VLOOKUP(D2,BaseType!A:A,1,FALSE())),D2<>"Struct"),"N","Y") -> Y
B3: =IF(ISBLANK(A3),"",IF(AND(ISNA(VLOOKUP(A3,Interface_T1GC!E:E,1,FALSE())),ISNA(VLOOKUP(A3,D:D,1,FALSE()))),"N","Y")) | C3: DynamicObjectList_ICM | D3: SomeIP_DynamicObjectList_BUS | E3: 1 | F3: =IF(AND(ISNA(VLOOKUP(D3,A:A,1,FALSE())),ISNA(VLOOKUP(D3,BaseType!A:A,1,FALSE())),D3<>"Struct"),"N","Y") -> Y | G3: 传输动态障碍物数据包
B4: =IF(ISBLANK(A4),"",IF(AND(ISNA(VLOOKUP(A4,Interface_T1GC!E:E,1,FALSE())),ISNA(VLOOKUP(A4,D:D,1,FALSE()))),"N","Y")) | C4: StaticObjectList_ICM | D4: SomeIP_StaticObjectList_BUS | E4: 1 | F4: =IF(AND(ISNA(VLOOKUP(D4,A:A,1,FALSE())),ISNA(VLOOKUP(D4,BaseType!A:A,1,FALSE())),D4<>"Struct"),"N","Y") -> Y | G4: 传输静态障碍物数据包
B5: =IF(ISBLANK(A5),"",IF(AND(ISNA(VLOOKUP(A5,Interface_T1GC!E:E,1,FALSE())),ISNA(VLOOKUP(A5,D:D,1,FALSE()))),"N","Y")) | C5: LaneLineList_ICM | D5: SomeIP_LaneLineList_BUS | E5: 1 | F5: =IF(AND(ISNA(VLOOKUP(D5,A:A,1,FALSE())),ISNA(VLOOKUP(D5,BaseType!A:A,1,FALSE())),D5<>"Struct"),"N","Y") -> Y | G5: 传输车道线数据包
B6: =IF(ISBLANK(A6),"",IF(AND(ISNA(VLOOKUP(A6,Interface_T1GC!E:E,1,FALSE())),ISNA(VLOOKUP(A6,D:D,1,FALSE()))),"N","Y")) | C6: PlanningPath_ICM | D6: SomeIP_PlanningPath_BUS | E6: 1 | F6: =IF(AND(ISNA(VLOOKUP(D6,A:A,1,FALSE())),ISNA(VLOOKUP(D6,BaseType!A:A,1,FALSE())),D6<>"Struct"),"N","Y") -> Y | G6: 传输规划轨迹数据包
B7: =IF(ISBLANK(A7),"",IF(AND(ISNA(VLOOKUP(A7,Interface_T1GC!E:E,1,FALSE())),ISNA(VLOOKUP(A7,D:D,1,FALSE()))),"N","Y")) | C7: Othersymbol_ICM | D7: SomeIP_Othersymbol_BUS | E7: 1 | F7: =IF(AND(ISNA(VLOOKUP(D7,A:A,1,FALSE())),ISNA(VLOOKUP(D7,BaseType!A:A,1,FALSE())),D7<>"Struct"),"N","Y") -> Y | G7: 传输其他符号信息
A8: SomeIP_DynamicObjectList_BUS | B8: =IF(ISBLANK(A8),"",IF(AND(ISNA(VLOOKUP(A8,Interface_T1GC!E:E,1,FALSE())),ISNA(VLOOKUP(A8,D:D,1,FALSE()))),"N","Y")) -> Y | D8: Struct | F8: =IF(AND(ISNA(VLOOKUP(D8,A:A,1,FALSE())),ISNA(VLOOKUP(D8,BaseType!A:A,1,FALSE())),D8<>"Struct"),"N","Y") -> Y
B9: =IF(ISBLANK(A9),"",IF(AND(ISNA(VLOOKUP(A9,Interface_T1GC!E:E,1,FALSE())),ISNA(VLOOKUP(A9,D:D,1,FALSE()))),"N","Y")) | C9: timestamp | D9: uint64 | E9: 1 | F9: =IF(AND(ISNA(VLOOKUP(D9,A:A,1,FALSE())),ISNA(VLOOKUP(D9,BaseType!A:A,1,FALSE())),D9<>"Struct"),"N","Y") -> Y | G9: 时间戳ms
B10: =IF(ISBLANK(A10),"",IF(AND(ISNA(VLOOKUP(A10,Interface_T1GC!E:E,1,FALSE())),ISNA(VLOOKUP(A10,D:D,1,FALSE()))),"N","Y")) | C10: ObjectCnt | D10: int32 | E10: 1 | F10: =IF(AND(ISNA(VLOOKUP(D10,A:A,1,FALSE())),ISNA(VLOOKUP(D10,BaseType!A:A,1,FALSE())),D10<>"Struct"),"N","Y") -> Y | G10: 障碍物个数
B11: =IF(ISBLANK(A11),"",IF(AND(ISNA(VLOOKUP(A11,Interface_T1GC!E:E,1,FALSE())),ISNA(VLOOKUP(A11,D:D,1,FALSE()))),"N","Y")) | C11: ObjectInfoList | D11: SomeIP_DynamicObjectInfo_BUS | E11: 9 | F11: =IF(AND(ISNA(VLOOKUP(D11,A:A,1,FALSE())),ISNA(VLOOKUP(D11,BaseType!A:A,1,FALSE())),D11<>"Struct"),"N","Y") -> Y | G11: 障碍物信息列表
A12: SomeIP_DynamicObjectInfo_BUS | B12: =IF(ISBLANK(A12),"",IF(AND(ISNA(VLOOKUP(A12,Interface_T1GC!E:E,1,FALSE())),ISNA(VLOOKUP(A12,D:D,1,FALSE()))),"N","Y")) -> Y | D12: Struct | F12: =IF(AND(ISNA(VLOOKUP(D12,A:A,1,FALSE())),ISNA(VLOOKUP(D12,BaseType!A:A,1,FALSE())),D12<>"Struct"),"N","Y") -> Y
B13: =IF(ISBLANK(A13),"",IF(AND(ISNA(VLOOKUP(A13,Interface_T1GC!E:E,1,FALSE())),ISNA(VLOOKUP(A13,D:D,1,FALSE()))),"N","Y")) | C13: ObjectID | D13: uint8 | E13: 1 | F13: =IF(AND(ISNA(VLOOKUP(D13,A:A,1,FALSE())),ISNA(VLOOKUP(D13,BaseType!A:A,1,FALSE())),D13<>"Struct"),"N","Y") -> Y | G13: 目标id
B14: =IF(ISBLANK(A14),"",IF(AND(ISNA(VLOOKUP(A14,Interface_T1GC!E:E,1,FALSE())),ISNA(VLOOKUP(A14,D:D,1,FALSE()))),"N","Y")) | C14: objectType | D14: uint8 | E14: 1 | F14: =IF(AND(ISNA(VLOOKUP(D14,A:A,1,FALSE())),ISNA(VLOOKUP(D14,BaseType!A:A,1,FALSE())),D14<>"Struct"),"N","Y") -> Y | G14: 目标类型 0x0: No type 0x1: Car 0x2: Truck 0x3: Motorcycle 0x4: Pedestrian 0x5: Cyclist 0x6: Bus 0x7:tricyle 0x8:SUV
B15: =IF(ISBLANK(A15),"",IF(AND(ISNA(VLOOKUP(A15,Interface_T1GC!E:E,1,FALSE())),ISNA(VLOOKUP(A15,D:D,1,FALSE()))),"N","Y")) | C15: movingStatus | D15: uint8 | E15: 1 | F15: =IF(AND(ISNA(VLOOKUP(D15,A:A,1,FALSE())),ISNA(VLOOKUP(D15,BaseType!A:A,1,FALSE())),D15<>"Struct"),"N","Y") -> Y | G15: 目标运动状态 0x0:unknown 0x1:moving 0x2:standstill
B16: =IF(ISBLANK(A16),"",IF(AND(ISNA(VLOOKUP(A16,Interface_T1GC!E:E,1,FALSE())),ISNA(VLOOKUP(A16,D:D,1,FALSE()))),"N","Y")) | C16: lightStatus | D16: uint8 | E16: 1 | F16: =IF(AND(ISNA(VLOOKUP(D16,A:A,1,FALSE())),ISNA(VLOOKUP(D16,BaseType!A:A,1,FALSE())),D16<>"Struct"),"N","Y") -> Y | G16: 目标灯光状态 0x0:None 0x1:Turnleft 0x2:Turnright 0x3:DoubleFlash 0x4:Brake 0x5: Reverse
B17: =IF(ISBLANK(A17),"",IF(AND(ISNA(VLOOKUP(A17,Interface_T1GC!E:E,1,FALSE())),ISNA(VLOOKUP(A17,D:D,1,FALSE()))),"N","Y")) | C17: objectPoseX | D17: single | E17: 1 | F17: =IF(AND(ISNA(VLOOKUP(D17,A:A,1,FALSE())),ISNA(VLOOKUP(D17,BaseType!A:A,1,FALSE())),D17<>"Struct"),"N","Y") -> Y | G17: 目标位置X坐标，单位cm
B18: =IF(ISBLANK(A18),"",IF(AND(ISNA(VLOOKUP(A18,Interface_T1GC!E:E,1,FALSE())),ISNA(VLOOKUP(A18,D:D,1,FALSE()))),"N","Y")) | C18: objectPoseY | D18: single | E18: 1 | F18: =IF(AND(ISNA(VLOOKUP(D18,A:A,1,FALSE())),ISNA(VLOOKUP(D18,BaseType!A:A,1,FALSE())),D18<>"Struct"),"N","Y") -> Y | G18: 目标位置Y坐标，单位cm
B19: =IF(ISBLANK(A19),"",IF(AND(ISNA(VLOOKUP(A19,Interface_T1GC!E:E,1,FALSE())),ISNA(VLOOKUP(A19,D:D,1,FALSE()))),"N","Y")) | C19: objectYaw | D19: single | E19: 1 | F19: =IF(AND(ISNA(VLOOKUP(D19,A:A,1,FALSE())),ISNA(VLOOKUP(D19,BaseType!A:A,1,FALSE())),D19<>"Struct"),"N","Y") -> Y | G19: 目标Yaw角，单位deg
B20: =IF(ISBLANK(A20),"",IF(AND(ISNA(VLOOKUP(A20,Interface_T1GC!E:E,1,FALSE())),ISNA(VLOOKUP(A20,D:D,1,FALSE()))),"N","Y")) | C20: objectPitch | D20: single | E20: 1 | F20: =IF(AND(ISNA(VLOOKUP(D20,A:A,1,FALSE())),ISNA(VLOOKUP(D20,BaseType!A:A,1,FALSE())),D20<>"Struct"),"N","Y") -> Y | G20: 目标Picth角，单位deg
B21: =IF(ISBLANK(A21),"",IF(AND(ISNA(VLOOKUP(A21,Interface_T1GC!E:E,1,FALSE())),ISNA(VLOOKUP(A21,D:D,1,FALSE()))),"N","Y")) | C21: objectRoll | D21: single | E21: 1 | F21: =IF(AND(ISNA(VLOOKUP(D21,A:A,1,FALSE())),ISNA(VLOOKUP(D21,BaseType!A:A,1,FALSE())),D21<>"Struct"),"N","Y") -> Y | G21: 目标Roll角，单位deg
B22: =IF(ISBLANK(A22),"",IF(AND(ISNA(VLOOKUP(A22,Interface_T1GC!E:E,1,FALSE())),ISNA(VLOOKUP(A22,D:D,1,FALSE()))),"N","Y")) | C22: objectLength | D22: uint16 | E22: 1 | F22: =IF(AND(ISNA(VLOOKUP(D22,A:A,1,FALSE())),ISNA(VLOOKUP(D22,BaseType!A:A,1,FALSE())),D22<>"Struct"),"N","Y") -> Y | G22: 目标长度，单位cm
B23: =IF(ISBLANK(A23),"",IF(AND(ISNA(VLOOKUP(A23,Interface_T1GC!E:E,1,FALSE())),ISNA(VLOOKUP(A23,D:D,1,FALSE()))),"N","Y")) | C23: objecWidth | D23: uint16 | E23: 1 | F23: =IF(AND(ISNA(VLOOKUP(D23,A:A,1,FALSE())),ISNA(VLOOKUP(D23,BaseType!A:A,1,FALSE())),D23<>"Struct"),"N","Y") -> Y | G23: 目标宽度，单位cm
B24: =IF(ISBLANK(A24),"",IF(AND(ISNA(VLOOKUP(A24,Interface_T1GC!E:E,1,FALSE())),ISNA(VLOOKUP(A24,D:D,1,FALSE()))),"N","Y")) | C24: objectHeight | D24: uint16 | E24: 1 | F24: =IF(AND(ISNA(VLOOKUP(D24,A:A,1,FALSE())),ISNA(VLOOKUP(D24,BaseType!A:A,1,FALSE())),D24<>"Struct"),"N","Y") -> Y | G24: 目标高度，单位cm
B25: =IF(ISBLANK(A25),"",IF(AND(ISNA(VLOOKUP(A25,Interface_T1GC!E:E,1,FALSE())),ISNA(VLOOKUP(A25,D:D,1,FALSE()))),"N","Y")) | C25: objectColor | D25: uint8 | E25: 1 | F25: =IF(AND(ISNA(VLOOKUP(D25,A:A,1,FALSE())),ISNA(VLOOKUP(D25,BaseType!A:A,1,FALSE())),D25<>"Struct"),"N","Y") -> Y | G25: 高亮显示 0x0: None 0x1: Grey 0x2: Blue 0x3: Yellow 0x4: Red
A26: SomeIP_StaticObjectList_BUS | B26: =IF(ISBLANK(A26),"",IF(AND(ISNA(VLOOKUP(A26,Interface_T1GC!E:E,1,FALSE())),ISNA(VLOOKUP(A26,D:D,1,FALSE()))),"N","Y")) -> Y | D26: Struct | F26: =IF(AND(ISNA(VLOOKUP(D26,A:A,1,FALSE())),ISNA(VLOOKUP(D26,BaseType!A:A,1,FALSE())),D26<>"Struct"),"N","Y") -> Y
B27: =IF(ISBLANK(A27),"",IF(AND(ISNA(VLOOKUP(A27,Interface_T1GC!E:E,1,FALSE())),ISNA(VLOOKUP(A27,D:D,1,FALSE()))),"N","Y")) | C27: timestamp | D27: uint64 | E27: 1 | F27: =IF(AND(ISNA(VLOOKUP(D27,A:A,1,FALSE())),ISNA(VLOOKUP(D27,BaseType!A:A,1,FALSE())),D27<>"Struct"),"N","Y") -> Y | G27: 时间戳ms
B28: =IF(ISBLANK(A28),"",IF(AND(ISNA(VLOOKUP(A28,Interface_T1GC!E:E,1,FALSE())),ISNA(VLOOKUP(A28,D:D,1,FALSE()))),"N","Y")) | C28: ObjectCnt | D28: int32 | E28: 1 | F28: =IF(AND(ISNA(VLOOKUP(D28,A:A,1,FALSE())),ISNA(VLOOKUP(D28,BaseType!A:A,1,FALSE())),D28<>"Struct"),"N","Y") -> Y | G28: 障碍物个数
B29: =IF(ISBLANK(A29),"",IF(AND(ISNA(VLOOKUP(A29,Interface_T1GC!E:E,1,FALSE())),ISNA(VLOOKUP(A29,D:D,1,FALSE()))),"N","Y")) | C29: ObjectInfoList | D29: SomeIP_StaticObjectInfo_BUS | E29: 9 | F29: =IF(AND(ISNA(VLOOKUP(D29,A:A,1,FALSE())),ISNA(VLOOKUP(D29,BaseType!A:A,1,FALSE())),D29<>"Struct"),"N","Y") -> Y | G29: 障碍物信息列表
A30: SomeIP_StaticObjectInfo_BUS | B30: =IF(ISBLANK(A30),"",IF(AND(ISNA(VLOOKUP(A30,Interface_T1GC!E:E,1,FALSE())),ISNA(VLOOKUP(A30,D:D,1,FALSE()))),"N","Y")) -> Y | D30: Struct | F30: =IF(AND(ISNA(VLOOKUP(D30,A:A,1,FALSE())),ISNA(VLOOKUP(D30,BaseType!A:A,1,FALSE())),D30<>"Struct"),"N","Y") -> Y
B31: =IF(ISBLANK(A31),"",IF(AND(ISNA(VLOOKUP(A31,Interface_T1GC!E:E,1,FALSE())),ISNA(VLOOKUP(A31,D:D,1,FALSE()))),"N","Y")) | C31: ObjectID | D31: uint8 | E31: 1 | F31: =IF(AND(ISNA(VLOOKUP(D31,A:A,1,FALSE())),ISNA(VLOOKUP(D31,BaseType!A:A,1,FALSE())),D31<>"Struct"),"N","Y") -> Y | G31: 目标id
B32: =IF(ISBLANK(A32),"",IF(AND(ISNA(VLOOKUP(A32,Interface_T1GC!E:E,1,FALSE())),ISNA(VLOOKUP(A32,D:D,1,FALSE()))),"N","Y")) | C32: objectType | D32: uint8 | E32: 1 | F32: =IF(AND(ISNA(VLOOKUP(D32,A:A,1,FALSE())),ISNA(VLOOKUP(D32,BaseType!A:A,1,FALSE())),D32<>"Struct"),"N","Y") -> Y | G32: 目标类型 0x0: No type 0x1:traffic_cone 0x2:water-barrier 0x3:tripod 0x4:trafficbollard/isolationbollard 0x5:crashBarrel
B33: =IF(ISBLANK(A33),"",IF(AND(ISNA(VLOOKUP(A33,Interface_T1GC!E:E,1,FALSE())),ISNA(VLOOKUP(A33,D:D,1,FALSE()))),"N","Y")) | C33: objectPoseX | D33: single | E33: 1 | F33: =IF(AND(ISNA(VLOOKUP(D33,A:A,1,FALSE())),ISNA(VLOOKUP(D33,BaseType!A:A,1,FALSE())),D33<>"Struct"),"N","Y") -> Y | G33: 目标位置X坐标
B34: =IF(ISBLANK(A34),"",IF(AND(ISNA(VLOOKUP(A34,Interface_T1GC!E:E,1,FALSE())),ISNA(VLOOKUP(A34,D:D,1,FALSE()))),"N","Y")) | C34: objectPoseY | D34: single | E34: 1 | F34: =IF(AND(ISNA(VLOOKUP(D34,A:A,1,FALSE())),ISNA(VLOOKUP(D34,BaseType!A:A,1,FALSE())),D34<>"Struct"),"N","Y") -> Y | G34: 目标位置Y坐标
B35: =IF(ISBLANK(A35),"",IF(AND(ISNA(VLOOKUP(A35,Interface_T1GC!E:E,1,FALSE())),ISNA(VLOOKUP(A35,D:D,1,FALSE()))),"N","Y")) | C35: objectYaw | D35: single | E35: 1 | F35: =IF(AND(ISNA(VLOOKUP(D35,A:A,1,FALSE())),ISNA(VLOOKUP(D35,BaseType!A:A,1,FALSE())),D35<>"Struct"),"N","Y") -> Y | G35: 目标Yaw角，单位deg
B36: =IF(ISBLANK(A36),"",IF(AND(ISNA(VLOOKUP(A36,Interface_T1GC!E:E,1,FALSE())),ISNA(VLOOKUP(A36,D:D,1,FALSE()))),"N","Y")) | C36: objectLength | D36: uint16 | E36: 1 | F36: =IF(AND(ISNA(VLOOKUP(D36,A:A,1,FALSE())),ISNA(VLOOKUP(D36,BaseType!A:A,1,FALSE())),D36<>"Struct"),"N","Y") -> Y | G36: 目标长度，单位cm
B37: =IF(ISBLANK(A37),"",IF(AND(ISNA(VLOOKUP(A37,Interface_T1GC!E:E,1,FALSE())),ISNA(VLOOKUP(A37,D:D,1,FALSE()))),"N","Y")) | C37: objecWidth | D37: uint16 | E37: 1 | F37: =IF(AND(ISNA(VLOOKUP(D37,A:A,1,FALSE())),ISNA(VLOOKUP(D37,BaseType!A:A,1,FALSE())),D37<>"Struct"),"N","Y") -> Y | G37: 目标宽度，单位cm
B38: =IF(ISBLANK(A38),"",IF(AND(ISNA(VLOOKUP(A38,Interface_T1GC!E:E,1,FALSE())),ISNA(VLOOKUP(A38,D:D,1,FALSE()))),"N","Y")) | C38: objectHeight | D38: uint16 | E38: 1 | F38: =IF(AND(ISNA(VLOOKUP(D38,A:A,1,FALSE())),ISNA(VLOOKUP(D38,BaseType!A:A,1,FALSE())),D38<>"Struct"),"N","Y") -> Y | G38: 目标高度，单位cm
A39: SomeIP_LaneLineList_BUS | B39: =IF(ISBLANK(A39),"",IF(AND(ISNA(VLOOKUP(A39,Interface_T1GC!E:E,1,FALSE())),ISNA(VLOOKUP(A39,D:D,1,FALSE()))),"N","Y")) -> Y | D39: Struct | F39: =IF(AND(ISNA(VLOOKUP(D39,A:A,1,FALSE())),ISNA(VLOOKUP(D39,BaseType!A:A,1,FALSE())),D39<>"Struct"),"N","Y") -> Y
B40: =IF(ISBLANK(A40),"",IF(AND(ISNA(VLOOKUP(A40,Interface_T1GC!E:E,1,FALSE())),ISNA(VLOOKUP(A40,D:D,1,FALSE()))),"N","Y")) | C40: timestamp | D40: uint64 | E40: 1 | F40: =IF(AND(ISNA(VLOOKUP(D40,A:A,1,FALSE())),ISNA(VLOOKUP(D40,BaseType!A:A,1,FALSE())),D40<>"Struct"),"N","Y") -> Y | G40: 时间戳ms
...

Sheet Interface_E01
A1: SWCName | B1: I/O | C1: PortType | D1: PortName/Operation | E1: Rte_Type/Return_Type | F1: RteTypeExist | G1: Description | H1: DataAccessMode | I1: IsQueued | J1: QueueLength | K1: InterfaceType | L1: IsService | M1: IsUpdated | N1: SignalType_Simple_Array_Record_ | O1: RecordTypedefName
A2: autosar_swc_val | B2: Inport | C2: S/R | D2: Fusa_CAN_E2E | E2: Fusa_CAN_E2E_BUS | F2: =IF(AND( ISNA(VLOOKUP(E2,DataType_E01!A:A,1,FALSE)), ISNA(VLOOKUP(E2,DataType_Platform!A:A,1,FALSE)), ISNA(VLOOKUP(E2,BaseType!A:A,1,FALSE))),"N","Y") -> Y | G2: 功能安全E2E信息 | H2: Explict | I2: N
A3: autosar_swc_val | B3: Inport | C3: S/R | D3: Fusa_CAN_Value | E3: Fusa_CAN_Value_BUS | F3: =IF(AND( ISNA(VLOOKUP(E3,DataType_E01!A:A,1,FALSE)), ISNA(VLOOKUP(E3,DataType_Platform!A:A,1,FALSE)), ISNA(VLOOKUP(E3,BaseType!A:A,1,FALSE))),"N","Y") -> Y | G3: 功能安全依赖矩阵信号 | H3: Explict | I3: N
A4: autosar_swc_val | B4: Inport | C4: S/R | D4: Fusa_ErrID | E4: Fusa_ErrID_BUS | F4: =IF(AND( ISNA(VLOOKUP(E4,DataType_E01!A:A,1,FALSE)), ISNA(VLOOKUP(E4,DataType_Platform!A:A,1,FALSE)), ISNA(VLOOKUP(E4,BaseType!A:A,1,FALSE))),"N","Y") -> Y | G4: 底层功能安全ErrID | H4: Explict | I4: N
A5: autosar_swc_val | B5: Inport | C5: S/R | D5: SysIn_HMI_ADASSetting | E5: SomeIP_HMI_ADASSetting_BUS | F5: =IF(AND( ISNA(VLOOKUP(E5,DataType_E01!A:A,1,FALSE)), ISNA(VLOOKUP(E5,DataType_Platform!A:A,1,FALSE)), ISNA(VLOOKUP(E5,BaseType!A:A,1,FALSE))),"N","Y") -> Y | G5: ADAS开关设置项 | H5: Explict | I5: N | L5: N
A6: autosar_swc_val | B6: Inport | C6: S/R | D6: SysIn_ICC_SDmapInfo_2 | E6: SomeIP_ICC_SDmapInfo_2_BUS | F6: =IF(AND( ISNA(VLOOKUP(E6,DataType_E01!A:A,1,FALSE)), ISNA(VLOOKUP(E6,DataType_Platform!A:A,1,FALSE)), ISNA(VLOOKUP(E6,BaseType!A:A,1,FALSE))),"N","Y") -> Y | G6: SD map output information | H6: Explict | I6: N | L6: N
A7: autosar_swc_val | B7: Outport | C7: S/R | D7: SysOut_FCM_DrivingHmiEnv | E7: SomeIP_FCM_DrivingHmiEnv_BUS | F7: =IF(AND( ISNA(VLOOKUP(E7,DataType_E01!A:A,1,FALSE)), ISNA(VLOOKUP(E7,DataType_Platform!A:A,1,FALSE)), ISNA(VLOOKUP(E7,BaseType!A:A,1,FALSE))),"N","Y") -> Y | G7: 人机交互环境重构 | H7: Explict | I7: N | M7: N
A8: autosar_swc_val | B8: Outport | C8: S/R | D8: SysOut_FCM_DrivingFuncInfo | E8: SomeIP_FCM_DrivingFuncInfo_BUS | F8: =IF(AND( ISNA(VLOOKUP(E8,DataType_E01!A:A,1,FALSE)), ISNA(VLOOKUP(E8,DataType_Platform!A:A,1,FALSE)), ISNA(VLOOKUP(E8,BaseType!A:A,1,FALSE))),"N","Y") -> Y | G8: 驾驶功能信息 | H8: Explict | I8: N | M8: N
A9: autosar_swc_val | B9: Outport | C9: S/R | D9: SysOut_FCM_ActiveSafetyInfo | E9: SomeIP_FCM_ActiveSafetyInfo_BUS | F9: =IF(AND( ISNA(VLOOKUP(E9,DataType_E01!A:A,1,FALSE)), ISNA(VLOOKUP(E9,DataType_Platform!A:A,1,FALSE)), ISNA(VLOOKUP(E9,BaseType!A:A,1,FALSE))),"N","Y") -> Y | G9: 主动安全信息 | H9: Explict | I9: N | M9: N
A10: autosar_swc_val | B10: Outport | C10: S/R | D10: SysOut_FCM_SensorInfo | E10: SomeIP_FCM_SensorInfo_BUS | F10: =IF(AND( ISNA(VLOOKUP(E10,DataType_E01!A:A,1,FALSE)), ISNA(VLOOKUP(E10,DataType_Platform!A:A,1,FALSE)), ISNA(VLOOKUP(E10,BaseType!A:A,1,FALSE))),"N","Y") -> Y | G10: ADAS 控制器及传感器状态信息服务 | H10: Explict | I10: N | M10: N
A11: autosar_swc_val | B11: Outport | C11: S/R | D11: SysOut_FCM_UUID | E11: SomeIP_SysOut_FCM_UUID_BUS | F11: =IF(AND( ISNA(VLOOKUP(E11,DataType_E01!A:A,1,FALSE)), ISNA(VLOOKUP(E11,DataType_Platform!A:A,1,FALSE)), ISNA(VLOOKUP(E11,BaseType!A:A,1,FALSE))),"N","Y") -> Y | G11: 车辆UUID信息 | H11: Explict | I11: N | M11: N
A12: autosar_swc_val | B12: Outport | C12: S/R | D12: SysOut_FCM_DVRSts | E12: SomeIP_SysOut_FCM_DVRSts_BUS | F12: =IF(AND( ISNA(VLOOKUP(E12,DataType_E01!A:A,1,FALSE)), ISNA(VLOOKUP(E12,DataType_Platform!A:A,1,FALSE)), ISNA(VLOOKUP(E12,BaseType!A:A,1,FALSE))),"N","Y") -> Y | G12: DVR状态反馈 | H12: Explict | I12: N | M12: N
A13: autosar_swc_fusion | B13: Inport | C13: S/R | D13: RR_CR_OBJ | E13: CR_OBJ_BUS | F13: =IF(AND(ISNA(VLOOKUP(E13,DataType_T1GC!A:A,1,FALSE())),ISNA(VLOOKUP(E13,BaseType!A:A,1,FALSE()))),"Y","Y") -> Y | H13: Explict | I13: N | M13: Y
A14: autosar_swc_fusion | B14: Inport | C14: S/R | D14: RL_CR_OBJ | E14: CR_OBJ_BUS | F14: =IF(AND(ISNA(VLOOKUP(E14,DataType_T1GC!A:A,1,FALSE())),ISNA(VLOOKUP(E14,BaseType!A:A,1,FALSE()))),"Y","Y") -> Y | H14: Explict | I14: N | M14: Y
A15: autosar_swc_dataclct | B15: Inport | C15: S/R | D15: Fusa_CAN_E2E | E15: Fusa_CAN_E2E_BUS | F15: =IF(AND( ISNA(VLOOKUP(E15,DataType_E01!A:A,1,FALSE)), ISNA(VLOOKUP(E15,DataType_Platform!A:A,1,FALSE)), ISNA(VLOOKUP(E15,BaseType!A:A,1,FALSE))),"N","Y") -> Y | H15: Explict | I15: N | K15: 0 | L15: 0 | M15: N
A16: autosar_swc_dataclct | B16: Inport | C16: S/R | D16: Fusa_ErrID | E16: Fusa_ErrID_BUS | F16: =IF(AND( ISNA(VLOOKUP(E16,DataType_E01!A:A,1,FALSE)), ISNA(VLOOKUP(E16,DataType_Platform!A:A,1,FALSE)), ISNA(VLOOKUP(E16,BaseType!A:A,1,FALSE))),"N","Y") -> Y | H16: Explict | I16: N
A17: autosar_swc_dataclct | B17: Outport | C17: S/R | D17: FUSA_10ms_Data | E17: FUSA_10ms_Data_BUS | F17: =IF(AND(ISNA(VLOOKUP(E17,DataType_E01!A:A,1,FALSE())),ISNA(VLOOKUP(E17,BaseType!A:A,1,FALSE()))),"N","Y") -> Y | H17: Explict | I17: N | M17: N

Sheet DataType_E01
A1: Data Type Name | B1: IsUsed | C1: Member(valid if Data Type is Struct or Enum) | D1: DataType/EnumValue | E1: Dimensions | F1: Data Type Exist | G1: Description | H1: Size(bits) | I1: Min | J1: Max | K1: Factor | L1: Offset | M1: Unit
A2: Fusa_CAN_E2E_BUS | B2: =IF(ISBLANK(A2),"",IF(AND(ISNA(VLOOKUP(A2,Interface_E01!E:E,1,FALSE())),ISNA(VLOOKUP(A2,D:D,1,FALSE()))),"N","Y")) -> Y | D2: Struct | F2: =IF(AND(ISNA(VLOOKUP(D2,A:A,1,FALSE())),ISNA(VLOOKUP(D2,BaseType!A:A,1,FALSE())),D2<>"Struct"),"N","Y") -> Y
C3: Fusa_ACU_1_CRC1_Error | D3: boolean | E3: 1 | F3: =IF(AND(ISNA(VLOOKUP(D3,A:A,1,FALSE())),ISNA(VLOOKUP(D3,BaseType!A:A,1,FALSE())),D3<>"Struct"),"N","Y") -> Y | G3: ACU_1_CRC1_Error E2E通讯故障错误
C4: Fusa_ACU_1_RollgCntr1_Error | D4: boolean | E4: 1 | F4: =IF(AND(ISNA(VLOOKUP(D4,A:A,1,FALSE())),ISNA(VLOOKUP(D4,BaseType!A:A,1,FALSE())),D4<>"Struct"),"N","Y") -> Y | G4: ACU_1_RollgCntr1_Error E2E通讯故障错误
C5: Fusa_ACU_2_CRC1_Error | D5: boolean | E5: 1 | F5: =IF(AND(ISNA(VLOOKUP(D5,A:A,1,FALSE())),ISNA(VLOOKUP(D5,BaseType!A:A,1,FALSE())),D5<>"Struct"),"N","Y") -> Y | G5: ACU_2_CRC1_Error E2E通讯故障错误
C6: Fusa_ACU_2_RollgCntr1_Error | D6: boolean | E6: 1 | F6: =IF(AND(ISNA(VLOOKUP(D6,A:A,1,FALSE())),ISNA(VLOOKUP(D6,BaseType!A:A,1,FALSE())),D6<>"Struct"),"N","Y") -> Y | G6: ACU_2_RollgCntr1_Error E2E通讯故障错误
C7: Fusa_ACU_2_Timeout | D7: boolean | E7: 1 | F7: =IF(AND(ISNA(VLOOKUP(D7,A:A,1,FALSE())),ISNA(VLOOKUP(D7,BaseType!A:A,1,FALSE())),D7<>"Struct"),"N","Y") -> Y | G7: ACU_2_Timeout 数据帧通讯超时
C8: Fusa_ACU_3_CRC1_Error | D8: boolean | E8: 1 | F8: =IF(AND(ISNA(VLOOKUP(D8,A:A,1,FALSE())),ISNA(VLOOKUP(D8,BaseType!A:A,1,FALSE())),D8<>"Struct"),"N","Y") -> Y | G8: ACU_3_CRC1_Error E2E通讯故障错误
C9: Fusa_ACU_3_RollgCntr1_Error | D9: boolean | E9: 1 | F9: =IF(AND(ISNA(VLOOKUP(D9,A:A,1,FALSE())),ISNA(VLOOKUP(D9,BaseType!A:A,1,FALSE())),D9<>"Struct"),"N","Y") -> Y | G9: ACU_3_RollgCntr1_Error E2E通讯故障错误
C10: Fusa_ACU_3_Timeout | D10: boolean | E10: 1 | F10: =IF(AND(ISNA(VLOOKUP(D10,A:A,1,FALSE())),ISNA(VLOOKUP(D10,BaseType!A:A,1,FALSE())),D10<>"Struct"),"N","Y") -> Y | G10: ACU_3_Timeout 数据帧通讯超时
C11: Fusa_EPB_R_1_CRC1_Error | D11: boolean | E11: 1 | F11: =IF(AND(ISNA(VLOOKUP(D11,A:A,1,FALSE())),ISNA(VLOOKUP(D11,BaseType!A:A,1,FALSE())),D11<>"Struct"),"N","Y") -> Y | G11: EPB_R_1_CRC1_Error E2E通讯故障错误
C12: Fusa_EPB_R_1_RollgCntr1_Error | D12: boolean | E12: 1 | F12: =IF(AND(ISNA(VLOOKUP(D12,A:A,1,FALSE())),ISNA(VLOOKUP(D12,BaseType!A:A,1,FALSE())),D12<>"Struct"),"N","Y") -> Y | G12: EPB_R_1_RollgCntr1_Error E2E通讯故障错误
C13: Fusa_EPB_R_1_CRC2_Error | D13: boolean | E13: 1 | F13: =IF(AND(ISNA(VLOOKUP(D13,A:A,1,FALSE())),ISNA(VLOOKUP(D13,BaseType!A:A,1,FALSE())),D13<>"Struct"),"N","Y") -> Y | G13: EPB_R_1_CRC2_Error E2E通讯故障错误
C14: Fusa_EPB_R_1_RollgCntr2_Error | D14: boolean | E14: 1 | F14: =IF(AND(ISNA(VLOOKUP(D14,A:A,1,FALSE())),ISNA(VLOOKUP(D14,BaseType!A:A,1,FALSE())),D14<>"Struct"),"N","Y") -> Y | G14: EPB_R_1_RollgCntr2_Error E2E通讯故障错误
... C171: Fusa_VCC_3_RollgCntr_Error | D171: boolean | E171: 1 | F171: =IF(AND(ISNA(VLOOKUP(D171,A:A,1,FALSE())),ISNA(VLOOKUP(D171,BaseType!A:A,1,FALSE())),D171<>"Struct"),"N","Y") -> Y | G171: VCC_3_RollgCntr_Error E2E通讯故障错误
A172: Fusa_CAN_Value_BUS | B172: =IF(ISBLANK(A172),"",IF(AND(ISNA(VLOOKUP(A172,Interface_E01!E:E,1,FALSE())),ISNA(VLOOKUP(A172,D:D,1,FALSE()))),"N","Y")) -> Y | D172: Struct | E172: 1 | F172: =IF(AND(ISNA(VLOOKUP(D172,A:A,1,FALSE())),ISNA(VLOOKUP(D172,BaseType!A:A,1,FALSE())),D172<>"Struct"),"N","Y") -> Y
C173: Fusa_ACU_2_LateralAcceleration | D173: single | E173: 1 | F173: =IF(AND(ISNA(VLOOKUP(D173,A:A,1,FALSE())),ISNA(VLOOKUP(D173,BaseType!A:A,1,FALSE())),D173<>"Struct"),"N","Y") -> Y | G173: CAN矩阵输入信号: 描述:Lateral acceleration signal Sensor accuracy：0.0027680342857143g 信号值:
C174: Fusa_ACU_2_YawRate | D174: single | E174: 1 | F174: =IF(AND(ISNA(VLOOKUP(D174,A:A,1,FALSE())),ISNA(VLOOKUP(D174,BaseType!A:A,1,FALSE())),D174<>"Struct"),"N","Y") -> Y | G174: CAN矩阵输入信号: 描述:Yaw rate signal Sensor accuracy：0.122189236 deg/s 信号值:
C175: Fusa_ACU_2_YASCalibrationSts | D175: boolean | E175: 1 | F175: =IF(AND(ISNA(VLOOKUP(D175,A:A,1,FALSE())),ISNA(VLOOKUP(D175,BaseType!A:A,1,FALSE())),D175<>"Struct"),"N","Y") -> Y | G175: CAN矩阵输入信号: 描述:Indicates IMU Calibration State 信号值: 0x0:Sensor Not Calibrated 0x1:Sensor Calibrated
C176: Fusa_ACU_2_YawrateSigValidData | D176: uint8 | E176: 1 | F176: =IF(AND(ISNA(VLOOKUP(D176,A:A,1,FALSE())),ISNA(VLOOKUP(D176,BaseType!A:A,1,FALSE())),D176<>"Struct"),"N","Y") -> Y | G176: CAN矩阵输入信号: 描述:Signal state for yawrate 信号值: 0x0:Valid 0x1:Reserved 0x2:Invalid 0x3:Initialize
C177: Fusa_ACU_2_LateralAccelerationSigVD | D177: uint8 | E177: 1 | F177: =IF(AND(ISNA(VLOOKUP(D177,A:A,1,FALSE())),ISNA(VLOOKUP(D177,BaseType!A:A,1,FALSE())),D177<>"Struct"),"N","Y") -> Y | G177: CAN矩阵输入信号: 描述:If hasn’t been calibrated, after initialization, this signal ‘s value is always 10(invalid). 信号值: 0x0:Valid 0x1:Reserved 0x2:Invalid 0x3:Initialize
C178: Fusa_ACU_3_LongitudinalAcceleration | D178: single | E178: 1 | F178: =IF(AND(ISNA(VLOOKUP(D178,A:A,1,FALSE())),ISNA(VLOOKUP(D178,BaseType!A:A,1,FALSE())),D178<>"Struct"),"N","Y") -> Y | G178: CAN矩阵输入信号: 描述:Longitudinal acceleration signal Sensor accuracy：0.0027680342857143 g 信号值:
C179: Fusa_ACU_3_LongitudinalAccelerationVD | D179: uint8 | E179: 1 | F179: =IF(AND(ISNA(VLOOKUP(D179,A:A,1,FALSE())),ISNA(VLOOKUP(D179,BaseType!A:A,1,FALSE())),D179<>"Struct"),"N","Y") -> Y | G179: CAN矩阵输入信号: 描述:If hasn’t been calibrated, after initialization, this signal ‘s value is always10(invalid) 信号值: 0x0:Valid 0x1:Reserved 0x2:Invalid 0x3:Initialize
C180: Fusa_ACU_3_CrashOutputSts | D180: uint8 | E180: 1 | F180: =IF(AND(ISNA(VLOOKUP(D180,A:A,1,FALSE())),ISNA(VLOOKUP(D180,BaseType!A:A,1,FALSE())),D180<>"Struct"),"N","Y") -> Y | G180: CAN矩阵输入信号: 描述:Crash signal indicates the status according to bit: If multiple directions collide at the same time, each collision flag bit representing each direction will be set to 1.For example, if left crash is superimposed with right crash, the output signal is 00001100 此信号发到ECU停止工作为止 信号值: 0x00:No crash 0x01:Belt Crash 0x02:Front Crash 0x04:Left Side Crash 0x08:Right Side Crash 0x10:Rear Crash 0x20:Roll Crash
C181: Fusa_EPB_1_ActrSt | D181: uint8 | E181: 1 | F181: =IF(AND(ISNA(VLOOKUP(D181,A:A,1,FALSE())),ISNA(VLOOKUP(D181,BaseType!A:A,1,FALSE())),D181<>"Struct"),"N","Y") -> Y | G181: CAN矩阵输入信号: 描述:Current state of APB actuator connected to ECU EPB卡钳执行状态 信号值: 0x0:Unknow 0x1:Applied 0x2:Released 0x3:Applying 0x4:Releasing 0x5:CompletelyReleased 0x6:Half Applied 0x7:Reserved
C182: Fusa_EPB_1_EPBAvlSt | D182: boolean | E182: 1 | F182: =IF(AND(ISNA(VLOOKUP(D182,A:A,1,FALSE())),ISNA(VLOOKUP(D182,BaseType!A:A,1,FALSE())),D182<>"Struct"),"N","Y") -> Y | G182: CAN矩阵输入信号: 描述:EPB可用状态 信号值: 0x0:Not Available 0x1:Available
C183: Fusa_EPB_1_FltLvl | D183: uint8 | E183: 1 | F183: =IF(AND(ISNA(VLOOKUP(D183,A:A,1,FALSE())),ISNA(VLOOKUP(D183,BaseType!A:A,1,FALSE())),D183<>"Struct"),"N","Y") -> Y | G183: CAN矩阵输入信号: 描述:EPB故障状态 信号值: 0x0:No fault 0x1:One caliper fault-L 0x2:One caliper fault-R 0x3:Two caliper fault
C184: Fusa_EPB_R_1_Flt_Lamp | D184: uint8 | E184: 1 | F184: =IF(AND(ISNA(VLOOKUP(D184,A:A,1,FALSE())),ISNA(VLOOKUP(D184,BaseType!A:A,1,FALSE())),D184<>"Struct"),"N","Y") -> Y | G184: CAN矩阵输入信号: 描述:EPB故障状态 诊断和转毂测试模式时闪烁 信号值: 0x0:Lamp OFF 0x1:Lamp ON 0x2:Lamp Flash 0x3:Reserved
... C252: Fusa_RLCR_1_SysSt | D252: uint8 | E252: 1 | F252: =IF(AND(ISNA(VLOOKUP(D252,A:A,1,FALSE())),ISNA(VLOOKUP(D252,BaseType!A:A,1,FALSE())),D252<>"Struct"),"N","Y") -> Y | G252: CAN矩阵输入信号: 描述: 信号值: 0x0:Off 0x1:On 0x2:Temporary Error 0x3:System Error
A253: Fusa_ErrID_BUS | B253: =IF(ISBLANK(A253),"",IF(AND(ISNA(VLOOKUP(A253,Interface_E01!E:E,1,FALSE())),ISNA(VLOOKUP(A253,D:D,1,FALSE()))),"N","Y")) -> Y | D253: Struct | F253: =IF(AND(ISNA(VLOOKUP(D253,A:A,1,FALSE())),ISNA(VLOOKUP(D253,BaseType!A:A,1,FALSE())),D253<>"Struct"),"N","Y") -> Y
C254: Fusa_SerDes_MAX96717_1 | D254: uint8 | E254: 1 | F254: =IF(AND(ISNA(VLOOKUP(D254,A:A,1,FALSE())),ISNA(VLOOKUP(D254,BaseType!A:A,1,FALSE())),D254<>"Struct"),"N","Y") -> Y | G254: MAX96717 #1 fusa fault BitMap: bit[0]->Fusa_I2C_UART_MSGCNTR_ERR_1 bit[1]->Fusa_I2C_UART_CRC_ERR_1 bit[2]->Fusa_MEM_ECC_ERR2_1 bit[3]->Fusa_MEM_ECC_ERR1_1 bit[4]->Fusa_REG_CRC_ERR_1 bit[5]->Fusa_POST_MBIST_ERR_1 bit[6]->Fusa_POST_LBIST_ERR_1 bit[7]->Fusa_Reserve
C255: Fusa_SerDes_MAX96717_2 | D255: uint8 | E255: 1 | F255: =IF(AND(ISNA(VLOOKUP(D255,A:A,1,FALSE())),ISNA(VLOOKUP(D255,BaseType!A:A,1,FALSE())),D255<>"Struct"),"N","Y") -> Y | G255: MAX96717 #2 fusa fault BitMap: bit[0]->Fusa_I2C_UART_MSGCNTR_ERR_2 bit[1]->Fusa_I2C_UART_CRC_ERR_2 bit[2]->Fusa_MEM_ECC_ERR2_2 bit[3]->Fusa_MEM_ECC_ERR1_2 bit[4]->Fusa_REG_CRC_ERR_2 bit[5]->Fusa_POST_MBIST_ERR_2 bit[6]->Fusa_POST_LBIST_ERR_2 bit[7]->Fusa_Reserve
C256: Fusa_SerDes_MAX96716 | D256: uint16 | E256: 1 | F256: =IF(AND(ISNA(VLOOKUP(D256,A:A,1,FALSE())),ISNA(VLOOKUP(D256,BaseType!A:A,1,FALSE())),D256<>"Struct"),"N","Y") -> Y | G256: MAX96716 fusa fault BitMap: bit[0]->Fusa_TUN_DATA_CRC_ERR bit[1]->Fusa_TUN_ECC_UNCORR_ERR bit[2]->Fusa_TUN_ECC_CORR_ERR bit[3]->Fusa_VID_OVERFLOW_ERR bit[4]->Fusa_FSYNC_ERR bit[5]->Fusa_LCRC_ERR bit[6]->Fusa_VPRBS_ERR bit[7]->Fusa_I2C_UART_MSGCNTR_ERR bit[8]->Fusa_I2C_UART_CRC_ERR bit[9]->Fusa_96716_MEM_ECC_ERR2 bit[10]->Fusa_96716_MEM_ECC_ERR1 bit[11]->Fusa_REG_CRC_ERR bit[12]->Fusa_POST_MBIST_ERR bit[13]->Fusa_POST_LBIST_ERR bit[14]->Fusa_WM_ERR bit[15]->Fusa_Reserve
